Workbook

Sheet Program Remedial Kelas 4 a,
F1: PROGRAM REMEDIAL DAN PENGAYAAN | AH1: =F1 -> PROGRAM REMEDIAL DAN PENGAYAAN | AP1: =AH1 -> PROGRAM REMEDIAL DAN PENGAYAAN
F2: TAHUN PELAJARAN 2025 / 2026 | AH2: =F2 -> TAHUN PELAJARAN 2025 / 2026 | AP2: =AH2 -> TAHUN PELAJARAN 2025 / 2026
H4: : | I4: IV A/1 | S4: Kelas / Semester | T4: : IV A/1 | AH4: Kelas / Semester | AP4: Kelas / Semester | AV4: : | AW4: =#REF! -> #REF!
H5: : | I5: ='oke Lingk. 1'!L5 -> 0 | S5: Mata Pelajaran | T5: : PAI dan Budi Pekerti | AH5: Mata Pelajaran | AP5: Mata Pelajaran | AV5: : | AW5: =#REF! -> #REF!
H6: : | I6: Mari Kita Mengaji dan Mengkaji Q.S. Al-Ḥujurāt/49:13 dan Hadis Keragaman | S6: Materi Pokok | T6: : Mari Kita Mengaji dan Mengkaji Q.S. Al-Ḥujurāt/49:13 dan Hadis Keragaman | AH6: Lingkup Materi | AP6: Lingkup Materi | AV6: : | AW6: {=S6T6} -> #NAME?
A8: NO | B8: NAMA SISWA | E8: Kode TP 1 | S8: Alqur'an dan Hadis | AC8: Kode B.2 | AG8: Kode B.3 | AO8: Kode TP …......... | BD8: Kode TP ….........
E9: Nilai Minimal | F9: 1 | G9: 2 | H9: 3 | I9: 4 | J9: 5 | K9: 6 | L9: 7 | M9: 8 | N9: 9 | O9: 10 | Q9: Skor | R9: Nilai Akhir | S9: Jenis Program | T9: Nilai Sebelum Pengayaan | U9: Nilai Sesudah Pengayaan | V9: Keterangan | W9: 6 | X9: 7 | Y9: 8 | Z9: 9 | AA9: 10 | AC9: Jenis Program | AD9: Nilai Sebelum Pengayaan | AE9: Nilai Sesudah Pengayaan | AF9: Keterangan | AG9: Jenis Program | AH9: Nilai Sebelum Pengayaan | AI9: Nilai Sesudah Pengayaan | AJ9: Keterangan | AO9: Nilai Minimal | AP9: 1 | AQ9: 2 | AR9: 3 | AS9: 4 | AT9: 5 | AU9: 6 | AV9: 7 | AW9: 8 | AX9: 9 | AY9: 10 | BA9: Skor | BB9: Nilai Akhir | BC9: Tindak Lanjut | BD9: Nilai Minimal | BE9: 1 | BF9: 2 | BG9: 3 | BH9: 4 | BI9: 5 | BJ9: 6 | BK9: 7 | BL9: 8 | BM9: 9 | BN9: 10 | BP9: Skor | BQ9: Nilai Akhir | BR9: Tindak Lanjut
F10: Skor Maks Tiap Soal | AP10: Skor Maksimal Tiap Soal | BE10: Skor Maksimal Tiap Soal
F11: 2 | G11: 2 | H11: 2 | I11: 2 | J11: 2 | K11: 1 | L11: 1 | M11: 1 | N11: 1 | O11: 2 | P11: 10 | X11: 1 | Y11: 1 | Z11: 1 | AA11: 2 | AP11: 1 | AQ11: 1 | AR11: 1 | AS11: 1 | AT11: 1 | AU11: 1 | AV11: 1 | AW11: 1 | AX11: 1 | AY11: 2 | AZ11: =SUM(AP11:AY11) -> 11 | BE11: 1 | BF11: 1 | BG11: 1 | BH11: 1 | BI11: 1 | BJ11: 1 | BK11: 1 | BL11: 1 | BM11: 1 | BN11: 2 | BO11: =SUM(BE11:BN11) -> 11
A12: 1 | B12: Adittia Purnama | E12: 70 | F12: 0 | G12: 2 | H12: 2 | I12: 2 | J12: 0 | Q12: =SUM(F12:O12) -> 6 | R12: =Q12/P11*100 -> 60 | S12: Pengayaan | T12: 80 | U12: 80 | V12: Tuntas | AC12: Pengayaan | AD12: 80 | AE12: 80 | AF12: Tuntas | AG12: Pengayaan | AH12: 80 | AI12: 80 | AJ12: Tuntas | AO12: 65 | AP12: 1 | AQ12: 1 | AR12: 1 | AS12: 1 | AT12: 1 | AU12: 1 | AV12: 1 | AW12: 1 | AX12: 1 | AY12: 2 | BA12: =SUM(AP12:AY12) -> 11 | BB12: =BA12/AZ11*100 -> 100 | BC12: =IFERROR(IF(BB12<AO12,"Perbaiakan",IF(BB12>=AO12,"Pengayaan","")),"") -> Pengayaan | BP12: =SUM(BE12:BN12) -> 0 | BQ12: =BP12/BO11*100 -> 0 | BR12: =IFERROR(IF(BQ12<BD12,"Perbaiakan",IF(BQ12>=BD12,"Pengayaan","")),"") -> Pengayaan
A13: 2 | B13: Adrian Pratama Putra | E13: 70 | F13: 0 | G13: 2 | H13: 2 | I13: 2 | J13: 2 | Q13: =SUM(F13:O13) -> 8 | R13: =Q13/P11*100 -> 80 | S13: =IFERROR(IF(R13<E13,"Perbaiakan",IF(R13>=E13,"Pengayaan","")),"") -> Pengayaan | T13: 90 | U13: 90 | V13: Tuntas | AC13: Pengayaan | AD13: 80 | AE13: 80 | AF13: Tuntas | AG13: Pengayaan | AH13: 100 | AI13: 100 | AJ13: Tuntas | AO13: 60 | AP13: 1 | AQ13: 1 | AR13: 1 | AS13: 1 | AT13: 1 | AU13: 1 | BA13: =SUM(AP13:AY13) -> 6 | BB13: =BA13/AZ11*100 -> 54.545455 | BC13: =IFERROR(IF(BB13<AO13,"Perbaiakan",IF(BB13>=AO13,"Pengayaan","")),"") -> Perbaiakan | BP13: =SUM(BE13:BN13) -> 0 | BQ13: =BP13/BO11*100 -> 0 | BR13: =IFERROR(IF(BQ13<BD13,"Perbaiakan",IF(BQ13>=BD13,"Pengayaan","")),"") -> Pengayaan
A14: 3 | B14: AFRIZAL HERDIANSAH | E14: 70 | F14: 2 | G14: 0 | H14: 2 | I14: 2 | J14: 2 | Q14: =SUM(F14:O14) -> 8 | R14: =Q14/P11*100 -> 80 | S14: =IFERROR(IF(R14<E14,"Perbaikan",IF(R14>=E14,"Pengayaan","")),"") -> Pengayaan | T14: 85 | U14: 85 | V14: Tuntas | AC14: Pengayaan | AD14: 80 | AE14: 80 | AF14: Tuntas | AG14: Pengayaan | AH14: 80 | AI14: 80 | AJ14: Tuntas | BA14: =SUM(AP14:AY14) -> 0 | BB14: =BA14/AZ11*100 -> 0 | BC14: =IFERROR(IF(BB14<AO14,"Perbaiakan",IF(BB14>=AO14,"Pengayaan","")),"") -> Pengayaan | BP14: =SUM(BE14:BN14) -> 0 | BQ14: =BP14/BO11*100 -> 0 | BR14: =IFERROR(IF(BQ14<BD14,"Perbaiakan",IF(BQ14>=BD14,"Pengayaan","")),"") -> Pengayaan
A15: 4 | B15: Alif Zuanka Ramadani | E15: 70 | F15: 2 | G15: 2 | H15: 2 | I15: 0 | J15: 2 | Q15: =SUM(F15:O15) -> 8 | R15: =Q15/P11*100 -> 80 | S15: =IFERROR(IF(R15<E15,"Perbaiakan",IF(R15>=E15,"Pengayaan","")),"") -> Pengayaan | T15: 90 | U15: 90 | V15: Tuntas | AC15: Pengayaan | AD15: 80 | AE15: 80 | AF15: Tuntas | AG15: Pengayaan | AH15: 100 | AI15: 100 | AJ15: Tuntas | BA15: =SUM(AP15:AY15) -> 0 | BB15: =BA15/AZ11*100 -> 0 | BC15: =IFERROR(IF(BB15<AO15,"Perbaiakan",IF(BB15>=AO15,"Pengayaan","")),"") -> Pengayaan | BP15: =SUM(BE15:BN15) -> 0 | BQ15: =BP15/BO11*100 -> 0 | BR15: =IFERROR(IF(BQ15<BD15,"Perbaiakan",IF(BQ15>=BD15,"Pengayaan","")),"") -> Pengayaan
A16: 5 | B16: Alik Pramana | E16: 70 | F16: 0 | G16: 0 | H16: 2 | I16: 2 | J16: 0 | Q16: =SUM(F16:O16) -> 4 | R16: =Q16/P11*100 -> 40 | S16: =IFERROR(IF(R16<E16,"Perbaikan",IF(R16>=E16,"Pengayaan","")),"") -> Perbaikan | T16: 55 | U16: 70 | V16: Tuntas | AC16: Pengayaan | AD16: 80 | AE16: 80 | AF16: Tuntas | AG16: Perbaikan | AH16: 60 | AI16: 70 | AJ16: Tuntas | BA16: =SUM(AP16:AY16) -> 0 | BB16: =BA16/AZ11*100 -> 0 | BC16: =IFERROR(IF(BB16<AO16,"Perbaiakan",IF(BB16>=AO16,"Pengayaan","")),"") -> Pengayaan | BP16: =SUM(BE16:BN16) -> 0 | BQ16: =BP16/BO11*100 -> 0 | BR16: =IFERROR(IF(BQ16<BD16,"Perbaiakan",IF(BQ16>=BD16,"Pengayaan","")),"") -> Pengayaan
A17: 6 | B17: Alya Novitasari | E17: 70 | F17: 2 | G17: 2 | H17: 2 | I17: 2 | J17: 0 | Q17: =SUM(F17:O17) -> 8 | R17: =Q17/P11*100 -> 80 | S17: =IFERROR(IF(R17<E17,"Perbaiakan",IF(R17>=E17,"Pengayaan","")),"") -> Pengayaan | T17: 90 | U17: 90 | V17: Tuntas | AC17: Perbaikan | AD17: 60 | AE17: 70 | AF17: Tuntas | AG17: Pengayaan | AH17: 80 | AI17: 80 | AJ17: Tuntas | BA17: =SUM(AP17:AY17) -> 0 | BB17: =BA17/AZ11*100 -> 0 | BC17: =IFERROR(IF(BB17<AO17,"Perbaiakan",IF(BB17>=AO17,"Pengayaan","")),"") -> Pengayaan | BP17: =SUM(BE17:BN17) -> 0 | BQ17: =BP17/BO11*100 -> 0 | BR17: =IFERROR(IF(BQ17<BD17,"Perbaiakan",IF(BQ17>=BD17,"Pengayaan","")),"") -> Pengayaan
A18: 7 | B18: Anindita Keisha Zahra | E18: 70 | F18: 2 | G18: 2 | H18: 2 | I18: 2 | J18: 0 | Q18: =SUM(F18:O18) -> 8 | R18: =Q18/P11*100 -> 80 | S18: =IFERROR(IF(R18<E18,"Perbaiakan",IF(R18>=E18,"Pengayaan","")),"") -> Pengayaan | T18: 75 | U18: 75 | V18: Tuntas | AC18: Pengayaan | AD18: 80 | AE18: 80 | AF18: Tuntas | AG18: Pengayaan | AH18: 80 | AI18: 80 | AJ18: Tuntas | BA18: =SUM(AP18:AY18) -> 0 | BB18: =BA18/AZ11*100 -> 0 | BC18: =IFERROR(IF(BB18<AO18,"Perbaiakan",IF(BB18>=AO18,"Pengayaan","")),"") -> Pengayaan | BP18: =SUM(BE18:BN18) -> 0 | BQ18: =BP18/BO11*100 -> 0 | BR18: =IFERROR(IF(BQ18<BD18,"Perbaiakan",IF(BQ18>=BD18,"Pengayaan","")),"") -> Pengayaan
A19: 8 | B19: AQILLA FARIZA FIRMANSYAH | E19: 70 | F19: 2 | G19: 2 | H19: 2 | I19: 2 | J19: 2 | Q19: =SUM(F19:O19) -> 10 | R19: =Q19/P11*100 -> 100 | S19: =IFERROR(IF(R19<E19,"Perbaiakan",IF(R19>=E19,"Pengayaan","")),"") -> Pengayaan | T19: 75 | U19: 75 | V19: Tuntas | AC19: Pengayaan | AD19: 80 | AE19: 80 | AF19: Tuntas | AG19: Pengayaan | AH19: 80 | AI19: 80 | AJ19: Tuntas | BA19: =SUM(AP19:AY19) -> 0 | BB19: =BA19/AZ11*100 -> 0 | BC19: =IFERROR(IF(BB19<AO19,"Perbaiakan",IF(BB19>=AO19,"Pengayaan","")),"") -> Pengayaan | BP19: =SUM(BE19:BN19) -> 0 | BQ19: =BP19/BO11*100 -> 0 | BR19: =IFERROR(IF(BQ19<BD19,"Perbaiakan",IF(BQ19>=BD19,"Pengayaan","")),"") -> Pengayaan
A20: 9 | B20: Arkan Al Ghifari | E20: 70 | F20: 2 | G20: 2 | H20: 2 | I20: 0 | J20: 2 | Q20: =SUM(F20:O20) -> 8 | R20: =Q20/P11*100 -> 80 | S20: Perbaikan | T20: 85 | U20: 70 | V20: Tuntas | AC20: Pengayaan | AD20: 80 | AE20: 80 | AF20: Tuntas | AG20: Pengayaan | AH20: 80 | AI20: 80 | AJ20: Tuntas | BA20: =SUM(AP20:AY20) -> 0 | BB20: =BA20/AZ11*100 -> 0 | BC20: =IFERROR(IF(BB20<AO20,"Perbaiakan",IF(BB20>=AO20,"Pengayaan","")),"") -> Pengayaan | BP20: =SUM(BE20:BN20) -> 0 | BQ20: =BP20/BO11*100 -> 0 | BR20: =IFERROR(IF(BQ20<BD20,"Perbaiakan",IF(BQ20>=BD20,"Pengayaan","")),"") -> Pengayaan
A21: 10 | B21: Desti Amelia Putri | E21: 70 | F21: 0 | G21: 0 | H21: 2 | I21: 0 | J21: 0 | Q21: =SUM(F21:O21) -> 2 | R21: =Q21/P11*100 -> 20 | S21: Pengayaan | T21: 70 | U21: 75 | V21: Tuntas | AC21: Perbaikan | AD21: 0 | AE21: 70 | AF21: Tuntas | AG21: Perbaikan | AH21: 0 | AI21: 70 | AJ21: Tuntas | BA21: =SUM(AP21:AY21) -> 0 | BB21: =BA21/AZ11*100 -> 0 | BC21: =IFERROR(IF(BB21<AO21,"Perbaiakan",IF(BB21>=AO21,"Pengayaan","")),"") -> Pengayaan | BP21: =SUM(BE21:BN21) -> 0 | BQ21: =BP21/BO11*100 -> 0 | BR21: =IFERROR(IF(BQ21<BD21,"Perbaiakan",IF(BQ21>=BD21,"Pengayaan","")),"") -> Pengayaan
A22: 11 | B22: Dimas Parel | E22: 70 | F22: 0 | G22: 0 | H22: 2 | I22: 2 | J22: 0 | Q22: =SUM(F22:O22) -> 4 | R22: =Q22/P11*100 -> 40 | S22: Pengayaan | T22: 50 | U22: 90 | V22: Tuntas | AC22: Perbaikan | AD22: 60 | AE22: 70 | AF22: Tuntas | AG22: Perbaikan | AH22: 60 | AI22: 70 | AJ22: Tuntas | BA22: =SUM(AP22:AY22) -> 0 | BB22: =BA22/AZ11*100 -> 0 | BC22: =IFERROR(IF(BB22<AO22,"Perbaiakan",IF(BB22>=AO22,"Pengayaan","")),"") -> Pengayaan | BP22: =SUM(BE22:BN22) -> 0 | BQ22: =BP22/BO11*100 -> 0 | BR22: =IFERROR(IF(BQ22<BD22,"Perbaiakan",IF(BQ22>=BD22,"Pengayaan","")),"") -> Pengayaan
A23: 12 | B23: DZAKY IZWAR RAMADHAN | E23: 70 | F23: 2 | G23: 0 | H23: 0 | I23: 2 | J23: 2 | Q23: =SUM(F23:O23) -> 6 | R23: =Q23/P11*100 -> 60 | S23: Pengayaan | T23: 85 | U23: 85 | V23: Tuntas | AC23: Perbaikan | AD23: 40 | AE23: 70 | AF23: Tuntas | AG23: Pengayaan | AH23: 100 | AI23: 100 | AJ23: Tuntas | BA23: =SUM(AP23:AY23) -> 0 | BB23: =BA23/AZ11*100 -> 0 | BC23: =IFERROR(IF(BB23<AO23,"Perbaiakan",IF(BB23>=AO23,"Pengayaan","")),"") -> Pengayaan | BP23: =SUM(BE23:BN23) -> 0 | BQ23: =BP23/BO11*100 -> 0 | BR23: =IFERROR(IF(BQ23<BD23,"Perbaiakan",IF(BQ23>=BD23,"Pengayaan","")),"") -> Pengayaan
A24: 13 | B24: Geneva Rahmi Agustina | E24: 70 | F24: 2 | G24: 2 | H24: 2 | I24: 2 | J24: 2 | Q24: =SUM(F24:J24) -> 10 | R24: =Q24/P11*100 -> 100 | S24: Pengayaan | T24: 95 | U24: 95 | V24: Tuntas | AC24: Pengayaan | AD24: 80 | AE24: 80 | AF24: Tuntas | AG24: Pengayaan | AH24: 80 | AI24: 80 | AJ24: Tuntas | BA24: =SUM(AP24:AY24) -> 0 | BB24: =BA24/AZ11*100 -> 0 | BC24: =IFERROR(IF(BB24<AO24,"Perbaiakan",IF(BB24>=AO24,"Pengayaan","")),"") -> Pengayaan | BP24: =SUM(BE24:BN24) -> 0 | BQ24: =BP24/BO11*100 -> 0 | BR24: =IFERROR(IF(BQ24<BD24,"Perbaiakan",IF(BQ24>=BD24,"Pengayaan","")),"") -> Pengayaan
A25: 14 | B25: KANAYA AZAHRA | E25: 70 | F25: 2 | G25: 2 | H25: 2 | I25: 2 | J25: 2 | Q25: =SUM(F25:O25) -> 10 | R25: =Q25/P11*100 -> 100 | S25: Pengayaan | T25: 90 | U25: 90 | V25: Tuntas | AC25: Pengayaan | AD25: 80 | AE25: 80 | AF25: Tuntas | AG25: Pengayaan | AH25: 100 | AI25: 100 | AJ25: Tuntas | BA25: =SUM(AP25:AY25) -> 0 | BB25: =BA25/AZ11*100 -> 0 | BC25: =IFERROR(IF(BB25<AO25,"Perbaiakan",IF(BB25>=AO25,"Pengayaan","")),"") -> Pengayaan | BP25: =SUM(BE25:BN25) -> 0 | BQ25: =BP25/BO11*100 -> 0 | BR25: =IFERROR(IF(BQ25<BD25,"Perbaiakan",IF(BQ25>=BD25,"Pengayaan","")),"") -> Pengayaan
A26: 15 | B26: Kanaya Valery Wibawa | E26: 70 | F26: 0 | G26: 2 | H26: 2 | I26: 2 | J26: 2 | Q26: =SUM(F26:O26) -> 8 | R26: =Q26/P11*100 -> 80 | S26: Pengayaan | T26: 90 | U26: 90 | V26: Tuntas | AC26: Perbaikan | AD26: 60 | AE26: 70 | AF26: Tuntas | AG26: Pengayaan | AH26: 80 | AI26: 80 | AJ26: Tuntas | BA26: =SUM(AP26:AY26) -> 0 | BB26: =BA26/AZ11*100 -> 0 | BC26: =IFERROR(IF(BB26<AO26,"Perbaiakan",IF(BB26>=AO26,"Pengayaan","")),"") -> Pengayaan | BP26: =SUM(BE26:BN26) -> 0 | BQ26: =BP26/BO11*100 -> 0 | BR26: =IFERROR(IF(BQ26<BD26,"Perbaiakan",IF(BQ26>=BD26,"Pengayaan","")),"") -> Pengayaan
A27: 16 | B27: KAYLA FAUZIYAH PUTRI | E27: 70 | F27: 0 | G27: 0 | H27: 0 | I27: 2 | J27: 2 | Q27: =SUM(F27:O27) -> 4 | R27: =Q27/P11*100 -> 40 | S27: Pengayaan | T27: 85 | U27: 85 | V27: Tuntas | AC27: Perbaikan | AD27: 60 | AE27: 70 | AF27: Tuntas | AG27: Pengayaan | AH27: 100 | AI27: 100 | AJ27: Tuntas | BA27: =SUM(AP27:AY27) -> 0 | BB27: =BA27/AZ11*100 -> 0 | BC27: =IFERROR(IF(BB27<AO27,"Perbaiakan",IF(BB27>=AO27,"Pengayaan","")),"") -> Pengayaan | BP27: =SUM(BE27:BN27) -> 0 | BQ27: =BP27/BO11*100 -> 0 | BR27: =IFERROR(IF(BQ27<BD27,"Perbaiakan",IF(BQ27>=BD27,"Pengayaan","")),"") -> Pengayaan
A28: 17 | B28: Meisya Indirawati | E28: 70 | F28: 2 | G28: 2 | H28: 2 | I28: 2 | J28: 2 | Q28: =SUM(F28:O28) -> 10 | R28: =Q28/P11*100 -> 100 | S28: Pengayaan | T28: 90 | U28: 90 | V28: Tuntas | AC28: Perbaikan | AD28: 60 | AE28: 70 | AF28: Tuntas | AG28: Pengayaan | AH28: 100 | AI28: 100 | AJ28: Tuntas | BA28: =SUM(AP28:AY28) -> 0 | BB28: =BA28/AZ11*100 -> 0 | BC28: =IFERROR(IF(BB28<AO28,"Perbaiakan",IF(BB28>=AO28,"Pengayaan","")),"") -> Pengayaan | BP28: =SUM(BE28:BN28) -> 0 | BQ28: =BP28/BO11*100 -> 0 | BR28: =IFERROR(IF(BQ28<BD28,"Perbaiakan",IF(BQ28>=BD28,"Pengayaan","")),"") -> Pengayaan
A29: 18 | B29: PUTRI ANDINI | E29: 70 | F29: 0 | G29: 2 | H29: 2 | I29: 2 | J29: 0 | Q29: =SUM(F29:O29) -> 6 | R29: =Q29/P11*100 -> 60 | S29: =IFERROR(IF(R29<E29,"Perbaikan",IF(R29>=E29,"Pengayaan","")),"") -> Perbaikan | T29: 50 | U29: 70 | V29: Tuntas | AC29: Pengayaan | AD29: 80 | AE29: 80 | AF29: Tuntas | AG29: Pengayaan | AH29: 100 | AI29: 100 | AJ29: Tuntas | BA29: =SUM(AP29:AY29) -> 0 | BB29: =BA29/AZ11*100 -> 0 | BC29: =IFERROR(IF(BB29<AO29,"Perbaiakan",IF(BB29>=AO29,"Pengayaan","")),"") -> Pengayaan | BP29: =SUM(BE29:BN29) -> 0 | BQ29: =BP29/BO11*100 -> 0 | BR29: =IFERROR(IF(BQ29<BD29,"Perbaiakan",IF(BQ29>=BD29,"Pengayaan","")),"") -> Pengayaan
B32: Mengetahui | U32: Banjar, Agustus 2025 | AG32: Banjar, Agustus 2025 | AQ32: =AI32 -> 0 | BK32: =#REF! -> #REF!
B33: Kepala UPTD SDN 1 Sukamukti | U33: Guru PAdBP | AG33: Guru PAdBP | AQ33: =AI33 -> 0 | BK33: =#REF! -> #REF!
B37: DUDUNG, S.Pd.SD | U37: ANISA NURBASARI, S.Pd.I | AG37: ANISA NURBASARI, S.Pd.I | AQ37: =AI37 -> 0 | BK37: =#REF! -> #REF!
B38: NIP. 197111101993071001 | U38: NIP. 198702092019032004 | AG38: NIP. 198702092019032004 | AQ38: =AI38 -> 0 | BK38: =#REF! -> #REF!

Sheet Program Remedial Kelas 4 b.
F1: PROGRAM REMEDIAL DAN PENGAYAAN | AH1: =F1 -> PROGRAM REMEDIAL DAN PENGAYAAN | AP1: =AH1 -> PROGRAM REMEDIAL DAN PENGAYAAN
F2: TAHUN PELAJARAN 2025 / 2026 | AH2: =F2 -> TAHUN PELAJARAN 2025 / 2026 | AP2: =AH2 -> TAHUN PELAJARAN 2025 / 2026
H4: : | I4: IV A/1 | S4: Kelas / Semester | T4: : IV B/1 | AH4: Kelas / Semester | AP4: Kelas / Semester | AV4: : | AW4: =#REF! -> #REF!
H5: : | I5: ='oke Lingk. 1'!L5 -> 0 | S5: Mata Pelajaran | T5: : PAI dan Budi Pekerti | AH5: Mata Pelajaran | AP5: Mata Pelajaran | AV5: : | AW5: =#REF! -> #REF!
H6: : | I6: Mari Kita Mengaji dan Mengkaji Q.S. Al-Ḥujurāt/49:13 dan Hadis Keragaman | S6: Materi Pokok | T6: : Mari Kita Mengaji dan Mengkaji Q.S. Al-Ḥujurāt/49:13 dan Hadis Keragaman | AH6: Lingkup Materi | AP6: Lingkup Materi | AV6: : | AW6: {=S6T6} -> #NAME?
A8: NO | B8: NAMA SISWA | E8: Kode TP 1 | S8: Alqur'an dan Hadis | AC8: Kode B.2 | AG8: Kode B.3 | AO8: Kode TP …......... | BD8: Kode TP ….........
E9: Nilai Minimal | F9: 1 | G9: 2 | H9: 3 | I9: 4 | J9: 5 | K9: 6 | L9: 7 | M9: 8 | N9: 9 | O9: 10 | Q9: Skor | R9: Nilai Akhir | S9: Jenis Program | T9: Nilai Sebelum Pengayaan | U9: Nilai Sesudah Pengayaan | V9: Keterangan | W9: 6 | X9: 7 | Y9: 8 | Z9: 9 | AA9: 10 | AC9: Jenis Program | AD9: Nilai Sebelum Pengayaan | AE9: Nilai Sesudah Pengayaan | AF9: Keterangan | AG9: Jenis Program | AH9: Nilai Sebelum Pengayaan | AI9: Nilai Sesudah Pengayaan | AJ9: Keterangan | AO9: Nilai Minimal | AP9: 1 | AQ9: 2 | AR9: 3 | AS9: 4 | AT9: 5 | AU9: 6 | AV9: 7 | AW9: 8 | AX9: 9 | AY9: 10 | BA9: Skor | BB9: Nilai Akhir | BC9: Tindak Lanjut | BD9: Nilai Minimal | BE9: 1 | BF9: 2 | BG9: 3 | BH9: 4 | BI9: 5 | BJ9: 6 | BK9: 7 | BL9: 8 | BM9: 9 | BN9: 10 | BP9: Skor | BQ9: Nilai Akhir | BR9: Tindak Lanjut
F10: Skor Maks Tiap Soal | AP10: Skor Maksimal Tiap Soal | BE10: Skor Maksimal Tiap Soal
F11: 2 | G11: 2 | H11: 2 | I11: 2 | J11: 2 | K11: 1 | L11: 1 | M11: 1 | N11: 1 | O11: 2 | P11: 10 | X11: 1 | Y11: 1 | Z11: 1 | AA11: 2 | AP11: 1 | AQ11: 1 | AR11: 1 | AS11: 1 | AT11: 1 | AU11: 1 | AV11: 1 | AW11: 1 | AX11: 1 | AY11: 2 | AZ11: =SUM(AP11:AY11) -> 11 | BE11: 1 | BF11: 1 | BG11: 1 | BH11: 1 | BI11: 1 | BJ11: 1 | BK11: 1 | BL11: 1 | BM11: 1 | BN11: 2 | BO11: =SUM(BE11:BN11) -> 11
A12: 1 | B12: FAREL ALDIYANSYAH | E12: 70 | F12: 0 | G12: 2 | H12: 2 | I12: 2 | J12: 0 | Q12: =SUM(F12:O12) -> 6 | R12: =Q12/P11*100 -> 60 | S12: Pengayaan | T12: 85 | U12: 85 | V12: Tuntas | AC12: Pengayaan | AD12: 80 | AE12: 80 | AF12: Tuntas | AG12: Pengayaan | AH12: 80 | AI12: 80 | AJ12: Tuntas | AO12: 65 | AP12: 1 | AQ12: 1 | AR12: 1 | AS12: 1 | AT12: 1 | AU12: 1 | AV12: 1 | AW12: 1 | AX12: 1 | AY12: 2 | BA12: =SUM(AP12:AY12) -> 11 | BB12: =BA12/AZ11*100 -> 100 | BC12: =IFERROR(IF(BB12<AO12,"Perbaiakan",IF(BB12>=AO12,"Pengayaan","")),"") -> Pengayaan | BP12: =SUM(BE12:BN12) -> 0 | BQ12: =BP12/BO11*100 -> 0 | BR12: =IFERROR(IF(BQ12<BD12,"Perbaiakan",IF(BQ12>=BD12,"Pengayaan","")),"") -> Pengayaan
A13: 2 | B13: Fathurahman Diaz Arbany | E13: 70 | F13: 0 | G13: 2 | H13: 2 | I13: 2 | J13: 2 | Q13: =SUM(F13:O13) -> 8 | R13: =Q13/P11*100 -> 80 | S13: Pengayaan | T13: 90 | U13: 90 | V13: Tuntas | AC13: Pengayaan | AD13: 80 | AE13: 80 | AF13: Tuntas | AG13: Pengayaan | AH13: 100 | AI13: 100 | AJ13: Tuntas | AO13: 60 | AP13: 1 | AQ13: 1 | AR13: 1 | AS13: 1 | AT13: 1 | AU13: 1 | BA13: =SUM(AP13:AY13) -> 6 | BB13: =BA13/AZ11*100 -> 54.545455 | BC13: =IFERROR(IF(BB13<AO13,"Perbaiakan",IF(BB13>=AO13,"Pengayaan","")),"") -> Perbaiakan | BP13: =SUM(BE13:BN13) -> 0 | BQ13: =BP13/BO11*100 -> 0 | BR13: =IFERROR(IF(BQ13<BD13,"Perbaiakan",IF(BQ13>=BD13,"Pengayaan","")),"") -> Pengayaan
A14: 3 | B14: Hamdan Muttaqin | E14: 70 | F14: 2 | G14: 0 | H14: 2 | I14: 2 | J14: 2 | Q14: =SUM(F14:O14) -> 8 | R14: =Q14/P11*100 -> 80 | S14: Pengayaan | T14: 90 | U14: 90 | V14: Tuntas | AC14: Pengayaan | AD14: 80 | AE14: 80 | AF14: Tuntas | AG14: Pengayaan | AH14: 80 | AI14: 80 | AJ14: Tuntas | BA14: =SUM(AP14:AY14) -> 0 | BB14: =BA14/AZ11*100 -> 0 | BC14: =IFERROR(IF(BB14<AO14,"Perbaiakan",IF(BB14>=AO14,"Pengayaan","")),"") -> Pengayaan | BP14: =SUM(BE14:BN14) -> 0 | BQ14: =BP14/BO11*100 -> 0 | BR14: =IFERROR(IF(BQ14<BD14,"Perbaiakan",IF(BQ14>=BD14,"Pengayaan","")),"") -> Pengayaan
A15: 4 | B15: MUHAMMAD IMAM MAULANA | E15: 70 | F15: 2 | G15: 2 | H15: 2 | I15: 0 | J15: 2 | Q15: =SUM(F15:O15) -> 8 | R15: =Q15/P11*100 -> 80 | S15: Perbaikan | T15: 55 | U15: 70 | V15: Tuntas | AC15: Pengayaan | AD15: 80 | AE15: 80 | AF15: Tuntas | AG15: Pengayaan | AH15: 100 | AI15: 100 | AJ15: Tuntas | BA15: =SUM(AP15:AY15) -> 0 | BB15: =BA15/AZ11*100 -> 0 | BC15: =IFERROR(IF(BB15<AO15,"Perbaiakan",IF(BB15>=AO15,"Pengayaan","")),"") -> Pengayaan | BP15: =SUM(BE15:BN15) -> 0 | BQ15: =BP15/BO11*100 -> 0 | BR15: =IFERROR(IF(BQ15<BD15,"Perbaiakan",IF(BQ15>=BD15,"Pengayaan","")),"") -> Pengayaan
A16: 5 | B16: MUHAMMAD REZA ADITYA | E16: 70 | F16: 0 | G16: 0 | H16: 2 | I16: 2 | J16: 0 | Q16: =SUM(F16:O16) -> 4 | R16: =Q16/P11*100 -> 40 | S16: Pengayaan | T16: 75 | U16: 75 | V16: Tuntas | AC16: Pengayaan | AD16: 80 | AE16: 80 | AF16: Tuntas | AG16: Perbaikan | AH16: 60 | AI16: 70 | AJ16: Tuntas | BA16: =SUM(AP16:AY16) -> 0 | BB16: =BA16/AZ11*100 -> 0 | BC16: =IFERROR(IF(BB16<AO16,"Perbaiakan",IF(BB16>=AO16,"Pengayaan","")),"") -> Pengayaan | BP16: =SUM(BE16:BN16) -> 0 | BQ16: =BP16/BO11*100 -> 0 | BR16: =IFERROR(IF(BQ16<BD16,"Perbaiakan",IF(BQ16>=BD16,"Pengayaan","")),"") -> Pengayaan
A17: 6 | B17: RAISA WINDRIYANI | E17: 70 | F17: 2 | G17: 2 | H17: 2 | I17: 2 | J17: 0 | Q17: =SUM(F17:O17) -> 8 | R17: =Q17/P11*100 -> 80 | S17: Pengayaan | T17: 90 | U17: 90 | V17: Tuntas | AC17: Perbaikan | AD17: 60 | AE17: 70 | AF17: Tuntas | AG17: Pengayaan | AH17: 80 | AI17: 80 | AJ17: Tuntas | BA17: =SUM(AP17:AY17) -> 0 | BB17: =BA17/AZ11*100 -> 0 | BC17: =IFERROR(IF(BB17<AO17,"Perbaiakan",IF(BB17>=AO17,"Pengayaan","")),"") -> Pengayaan | BP17: =SUM(BE17:BN17) -> 0 | BQ17: =BP17/BO11*100 -> 0 | BR17: =IFERROR(IF(BQ17<BD17,"Perbaiakan",IF(BQ17>=BD17,"Pengayaan","")),"") -> Pengayaan
A18: 7 | B18: Raivania Ramdani | E18: 70 | F18: 2 | G18: 2 | H18: 2 | I18: 2 | J18: 0 | Q18: =SUM(F18:O18) -> 8 | R18: =Q18/P11*100 -> 80 | S18: Pengayaan | T18: 75 | U18: 75 | V18: Tuntas | AC18: Pengayaan | AD18: 80 | AE18: 80 | AF18: Tuntas | AG18: Pengayaan | AH18: 80 | AI18: 80 | AJ18: Tuntas | BA18: =SUM(AP18:AY18) -> 0 | BB18: =BA18/AZ11*100 -> 0 | BC18: =IFERROR(IF(BB18<AO18,"Perbaiakan",IF(BB18>=AO18,"Pengayaan","")),"") -> Pengayaan | BP18: =SUM(BE18:BN18) -> 0 | BQ18: =BP18/BO11*100 -> 0 | BR18: =IFERROR(IF(BQ18<BD18,"Perbaiakan",IF(BQ18>=BD18,"Pengayaan","")),"") -> Pengayaan
A19: 8 | B19: Rangga Gustian Haryanto | E19: 70 | F19: 2 | G19: 2 | H19: 2 | I19: 2 | J19: 2 | Q19: =SUM(F19:O19) -> 10 | R19: =Q19/P11*100 -> 100 | S19: Pengayaan | T19: 75 | U19: 75 | V19: Tuntas | AC19: Pengayaan | AD19: 80 | AE19: 80 | AF19: Tuntas | AG19: Pengayaan | AH19: 80 | AI19: 80 | AJ19: Tuntas | BA19: =SUM(AP19:AY19) -> 0 | BB19: =BA19/AZ11*100 -> 0 | BC19: =IFERROR(IF(BB19<AO19,"Perbaiakan",IF(BB19>=AO19,"Pengayaan","")),"") -> Pengayaan | BP19: =SUM(BE19:BN19) -> 0 | BQ19: =BP19/BO11*100 -> 0 | BR19: =IFERROR(IF(BQ19<BD19,"Perbaiakan",IF(BQ19>=BD19,"Pengayaan","")),"") -> Pengayaan
A20: 9 | B20: REVA ROSLIANA | E20: 70 | F20: 2 | G20: 2 | H20: 2 | I20: 0 | J20: 2 | Q20: =SUM(F20:O20) -> 8 | R20: =Q20/P11*100 -> 80 | S20: Perbaikan | T20: 60 | U20: 70 | V20: Tuntas | AC20: Pengayaan | AD20: 80 | AE20: 80 | AF20: Tuntas | AG20: Pengayaan | AH20: 80 | AI20: 80 | AJ20: Tuntas | BA20: =SUM(AP20:AY20) -> 0 | BB20: =BA20/AZ11*100 -> 0 | BC20: =IFERROR(IF(BB20<AO20,"Perbaiakan",IF(BB20>=AO20,"Pengayaan","")),"") -> Pengayaan | BP20: =SUM(BE20:BN20) -> 0 | BQ20: =BP20/BO11*100 -> 0 | BR20: =IFERROR(IF(BQ20<BD20,"Perbaiakan",IF(BQ20>=BD20,"Pengayaan","")),"") -> Pengayaan
A21: 10 | B21: RIFAAZKIA SHAQILA NAFISA | E21: 70 | F21: 0 | G21: 0 | H21: 2 | I21: 0 | J21: 0 | Q21: =SUM(F21:O21) -> 2 | R21: =Q21/P11*100 -> 20 | S21: Pengayaan | T21: 80 | U21: 80 | V21: Tuntas | AC21: Perbaikan | AD21: 0 | AE21: 70 | AF21: Tuntas | AG21: Perbaikan | AH21: 0 | AI21: 70 | AJ21: Tuntas | BA21: =SUM(AP21:AY21) -> 0 | BB21: =BA21/AZ11*100 -> 0 | BC21: =IFERROR(IF(BB21<AO21,"Perbaiakan",IF(BB21>=AO21,"Pengayaan","")),"") -> Pengayaan | BP21: =SUM(BE21:BN21) -> 0 | BQ21: =BP21/BO11*100 -> 0 | BR21: =IFERROR(IF(BQ21<BD21,"Perbaiakan",IF(BQ21>=BD21,"Pengayaan","")),"") -> Pengayaan
A22: 11 | B22: RISMA YULIANTI | E22: 70 | F22: 0 | G22: 0 | H22: 2 | I22: 2 | J22: 0 | Q22: =SUM(F22:O22) -> 4 | R22: =Q22/P11*100 -> 40 | S22: Pengayaan | T22: 80 | U22: 80 | V22: Tuntas | AC22: Perbaikan | AD22: 60 | AE22: 70 | AF22: Tuntas | AG22: Perbaikan | AH22: 60 | AI22: 70 | AJ22: Tuntas | BA22: =SUM(AP22:AY22) -> 0 | BB22: =BA22/AZ11*100 -> 0 | BC22: =IFERROR(IF(BB22<AO22,"Perbaiakan",IF(BB22>=AO22,"Pengayaan","")),"") -> Pengayaan | BP22: =SUM(BE22:BN22) -> 0 | BQ22: =BP22/BO11*100 -> 0 | BR22: =IFERROR(IF(BQ22<BD22,"Perbaiakan",IF(BQ22>=BD22,"Pengayaan","")),"") -> Pengayaan
A23: 12 | B23: Safaringga | E23: 70 | F23: 2 | G23: 0 | H23: 0 | I23: 2 | J23: 2 | Q23: =SUM(F23:O23) -> 6 | R23: =Q23/P11*100 -> 60 | S23: Pengayaan | T23: 85 | U23: 85 | V23: Tuntas | AC23: Perbaikan | AD23: 40 | AE23: 70 | AF23: Tuntas | AG23: Pengayaan | AH23: 100 | AI23: 100 | AJ23: Tuntas | BA23: =SUM(AP23:AY23) -> 0 | BB23: =BA23/AZ11*100 -> 0 | BC23: =IFERROR(IF(BB23<AO23,"Perbaiakan",IF(BB23>=AO23,"Pengayaan","")),"") -> Pengayaan | BP23: =SUM(BE23:BN23) -> 0 | BQ23: =BP23/BO11*100 -> 0 | BR23: =IFERROR(IF(BQ23<BD23,"Perbaiakan",IF(BQ23>=BD23,"Pengayaan","")),"") -> Pengayaan
A24: 13 | B24: SALSABILA MERRY TRIYANI | E24: 70 | F24: 2 | G24: 2 | H24: 2 | I24: 2 | J24: 2 | Q24: =SUM(F24:J24) -> 10 | R24: =Q24/P11*100 -> 100 | S24: Perbaikan | T24: 55 | U24: 75 | V24: Tuntas | AC24: Pengayaan | AD24: 80 | AE24: 80 | AF24: Tuntas | AG24: Pengayaan | AH24: 80 | AI24: 80 | AJ24: Tuntas | BA24: =SUM(AP24:AY24) -> 0 | BB24: =BA24/AZ11*100 -> 0 | BC24: =IFERROR(IF(BB24<AO24,"Perbaiakan",IF(BB24>=AO24,"Pengayaan","")),"") -> Pengayaan | BP24: =SUM(BE24:BN24) -> 0 | BQ24: =BP24/BO11*100 -> 0 | BR24: =IFERROR(IF(BQ24<BD24,"Perbaiakan",IF(BQ24>=BD24,"Pengayaan","")),"") -> Pengayaan
A25: 14 | B25: SHELI RAMADHANI | E25: 70 | F25: 2 | G25: 2 | H25: 2 | I25: 2 | J25: 2 | Q25: =SUM(F25:O25) -> 10 | R25: =Q25/P11*100 -> 100 | S25: Pengayaan | T25: 90 | U25: 90 | V25: Tuntas | AC25: Pengayaan | AD25: 80 | AE25: 80 | AF25: Tuntas | AG25: Pengayaan | AH25: 100 | AI25: 100 | AJ25: Tuntas | BA25: =SUM(AP25:AY25) -> 0 | BB25: =BA25/AZ11*100 -> 0 | BC25: =IFERROR(IF(BB25<AO25,"Perbaiakan",IF(BB25>=AO25,"Pengayaan","")),"") -> Pengayaan | BP25: =SUM(BE25:BN25) -> 0 | BQ25: =BP25/BO11*100 -> 0 | BR25: =IFERROR(IF(BQ25<BD25,"Perbaiakan",IF(BQ25>=BD25,"Pengayaan","")),"") -> Pengayaan
A26: 15 | B26: Silvia Salsabilla | E26: 70 | F26: 0 | G26: 2 | H26: 2 | I26: 2 | J26: 2 | Q26: =SUM(F26:O26) -> 8 | R26: =Q26/P11*100 -> 80 | S26: Pengayaan | T26: 90 | U26: 90 | V26: Tuntas | AC26: Perbaikan | AD26: 60 | AE26: 70 | AF26: Tuntas | AG26: Pengayaan | AH26: 80 | AI26: 80 | AJ26: Tuntas | BA26: =SUM(AP26:AY26) -> 0 | BB26: =BA26/AZ11*100 -> 0 | BC26: =IFERROR(IF(BB26<AO26,"Perbaiakan",IF(BB26>=AO26,"Pengayaan","")),"") -> Pengayaan | BP26: =SUM(BE26:BN26) -> 0 | BQ26: =BP26/BO11*100 -> 0 | BR26: =IFERROR(IF(BQ26<BD26,"Perbaiakan",IF(BQ26>=BD26,"Pengayaan","")),"") -> Pengayaan
A27: 16 | B27: SINDY RAHAYU | E27: 70 | F27: 0 | G27: 0 | H27: 0 | I27: 2 | J27: 2 | Q27: =SUM(F27:O27) -> 4 | R27: =Q27/P11*100 -> 40 | S27: Pengayaan | T27: 85 | U27: 85 | V27: Tuntas | AC27: Perbaikan | AD27: 60 | AE27: 70 | AF27: Tuntas | AG27: Pengayaan | AH27: 100 | AI27: 100 | AJ27: Tuntas | BA27: =SUM(AP27:AY27) -> 0 | BB27: =BA27/AZ11*100 -> 0 | BC27: =IFERROR(IF(BB27<AO27,"Perbaiakan",IF(BB27>=AO27,"Pengayaan","")),"") -> Pengayaan | BP27: =SUM(BE27:BN27) -> 0 | BQ27: =BP27/BO11*100 -> 0 | BR27: =IFERROR(IF(BQ27<BD27,"Perbaiakan",IF(BQ27>=BD27,"Pengayaan","")),"") -> Pengayaan
A28: 17 | B28: VANIA MEYLISA PUTRI | E28: 70 | F28: 2 | G28: 2 | H28: 2 | I28: 2 | J28: 2 | Q28: =SUM(F28:O28) -> 10 | R28: =Q28/P11*100 -> 100 | S28: Pengayaan | T28: 90 | U28: 90 | V28: Tuntas | AC28: Perbaikan | AD28: 60 | AE28: 70 | AF28: Tuntas | AG28: Pengayaan | AH28: 100 | AI28: 100 | AJ28: Tuntas | BA28: =SUM(AP28:AY28) -> 0 | BB28: =BA28/AZ11*100 -> 0 | BC28: =IFERROR(IF(BB28<AO28,"Perbaiakan",IF(BB28>=AO28,"Pengayaan","")),"") -> Pengayaan | BP28: =SUM(BE28:BN28) -> 0 | BQ28: =BP28/BO11*100 -> 0 | BR28: =IFERROR(IF(BQ28<BD28,"Perbaiakan",IF(BQ28>=BD28,"Pengayaan","")),"") -> Pengayaan
B31: Mengetahui | U31: Banjar, Agustus 2025 | AG31: Banjar, Agustus 2025 | AQ31: =AI31 -> 0 | BK31: =#REF! -> #REF!
B32: Kepala UPTD SDN 1 Sukamukti | U32: Guru PAdBP | AG32: Guru PAdBP | AQ32: =AI32 -> 0 | BK32: =#REF! -> #REF!
B36: DUDUNG, S.Pd.SD | U36: ANISA NURBASARI, S.Pd.I | AG36: ANISA NURBASARI, S.Pd.I | AQ36: =AI36 -> 0 | BK36: =#REF! -> #REF!
B37: NIP. 197111101993071001 | U37: NIP. 198702092019032004 | AG37: NIP. 198702092019032004 | AQ37: =AI37 -> 0 | BK37: =#REF! -> #REF!

Sheet Program Remedial Kelas 3
G1: PROGRAM REMEDIAL DAN PENGAYAAN | AH1: =G1 -> PROGRAM REMEDIAL DAN PENGAYAAN | AP1: =AH1 -> PROGRAM REMEDIAL DAN PENGAYAAN
G2: TAHUN PELAJARAN 2025 / 2026 | AH2: =G2 -> TAHUN PELAJARAN 2025 / 2026 | AP2: =AH2 -> TAHUN PELAJARAN 2025 / 2026
G4: Kelas / Semester | M4: : | N4: I / 1 | Q4: : | R4: I/2 | V4: Kelas / Semester | Y4: : | Z4: I / 1 | AC4: : | AD4: III (Tiga) /1 | AH4: Kelas / Semester | AP4: Kelas / Semester | AV4: : | AW4: =#REF! -> #REF!
G5: Mata Pelajaran | M5: : | N5: PAI dan Budi Pekerti | Q5: : | R5: PAI dan Budi Pekerti | V5: Mata Pelajaran | Y5: : | Z5: PAI dan Budi Pekerti | AC5: : | AD5: PAI dan Budi Pekerti | AH5: Mata Pelajaran | AP5: Mata Pelajaran | AV5: : | AW5: =#REF! -> #REF!
G6: Sumatif TP 1 | M6: : | N6: Senang membaca al-qur'an | Q6: : | R6: Senang membaca al-qur'an | V6: Sumatif TP 1 | Y6: : | Z6: Senang membaca al-qur'an | AC6: : | AD6: Senang membaca al-qur'an | AH6: Lingkup Materi | AP6: Lingkup Materi | AV6: : | AW6: {=S6T6} -> #NAME?
A8: NO | B8: NISN/NIS | C8: NAMA SISWA | F8: Kode TP 1 | T8: Kode B.1 | AC8: Kode B.2 | AG8: Kode B.3 | AO8: Kode TP …......... | BD8: Kode TP ….........
F9: Nilai Minimal | G9: 1 | H9: 2 | I9: 3 | J9: 4 | K9: 5 | L9: 6 | M9: 7 | N9: 8 | O9: 9 | P9: 10 | R9: Skor | S9: Nilai Akhir | T9: Jenis Program | U9: Nilai Sebelum Pengayaan | V9: Nilai Sesudah Pengayaan | W9: Keterangan | X9: 6 | Y9: 7 | Z9: 8 | AA9: 9 | AB9: 10 | AC9: Jenis Program | AD9: Nilai Sebelum Pengayaan | AE9: Nilai Sesudah Pengayaan | AF9: Keterangan | AG9: Jenis Program | AH9: Nilai Sebelum Pengayaan | AI9: Nilai Sesudah Pengayaan | AJ9: Keterangan | AO9: Nilai Minimal | AP9: 1 | AQ9: 2 | AR9: 3 | AS9: 4 | AT9: 5 | AU9: 6 | AV9: 7 | AW9: 8 | AX9: 9 | AY9: 10 | BA9: Skor | BB9: Nilai Akhir | BC9: Tindak Lanjut | BD9: Nilai Minimal | BE9: 1 | BF9: 2 | BG9: 3 | BH9: 4 | BI9: 5 | BJ9: 6 | BK9: 7 | BL9: 8 | BM9: 9 | BN9: 10 | BP9: Skor | BQ9: Nilai Akhir | BR9: Tindak Lanjut
G10: Skor Maks Tiap Soal | AP10: Skor Maksimal Tiap Soal | BE10: Skor Maksimal Tiap Soal
G11: 2 | H11: 2 | I11: 2 | J11: 2 | K11: 2 | L11: 1 | M11: 1 | N11: 1 | O11: 1 | P11: 2 | Q11: 10 | Y11: 1 | Z11: 1 | AA11: 1 | AB11: 2 | AP11: 1 | AQ11: 1 | AR11: 1 | AS11: 1 | AT11: 1 | AU11: 1 | AV11: 1 | AW11: 1 | AX11: 1 | AY11: 2 | AZ11: =SUM(AP11:AY11) -> 11 | BE11: 1 | BF11: 1 | BG11: 1 | BH11: 1 | BI11: 1 | BJ11: 1 | BK11: 1 | BL11: 1 | BM11: 1 | BN11: 2 | BO11: =SUM(BE11:BN11) -> 11
A12: 1 | B12: 3163415080 / 232401001 | C12: ARGA SEFERAGIC | F12: 70 | G12: 0 | H12: 2 | I12: 2 | J12: 2 | K12: 0 | R12: =SUM(G12:P12) -> 6 | S12: =R12/Q11*100 -> 60 | T12: =IFERROR(IF(S12<F12,"Perbaikan",IF(S12>=F12,"Pengayaan","")),"") -> Perbaikan | U12: 60 | V12: 70 | W12: Tuntas | AC12: Pengayaan | AD12: 80 | AE12: 80 | AF12: Tuntas | AG12: Pengayaan | AH12: 80 | AI12: 80 | AJ12: Tuntas | AO12: 65 | AP12: 1 | AQ12: 1 | AR12: 1 | AS12: 1 | AT12: 1 | AU12: 1 | AV12: 1 | AW12: 1 | AX12: 1 | AY12: 2 | BA12: =SUM(AP12:AY12) -> 11 | BB12: =BA12/AZ11*100 -> 100 | BC12: =IFERROR(IF(BB12<AO12,"Perbaiakan",IF(BB12>=AO12,"Pengayaan","")),"") -> Pengayaan | BP12: =SUM(BE12:BN12) -> 0 | BQ12: =BP12/BO11*100 -> 0 | BR12: =IFERROR(IF(BQ12<BD12,"Perbaiakan",IF(BQ12>=BD12,"Pengayaan","")),"") -> Pengayaan
A13: 2 | B13: 3161997134 / 232401002 | C13: ARKHA ARDANA PUTRA | F13: 70 | G13: 0 | H13: 2 | I13: 2 | J13: 2 | K13: 2 | R13: =SUM(G13:P13) -> 8 | S13: =R13/Q11*100 -> 80 | T13: =IFERROR(IF(S13<F13,"Perbaiakan",IF(S13>=F13,"Pengayaan","")),"") -> Pengayaan | U13: 80 | V13: 80 | W13: Tuntas | AC13: Pengayaan | AD13: 80 | AE13: 80 | AF13: Tuntas | AG13: Pengayaan | AH13: 100 | AI13: 100 | AJ13: Tuntas | AO13: 60 | AP13: 1 | AQ13: 1 | AR13: 1 | AS13: 1 | AT13: 1 | AU13: 1 | BA13: =SUM(AP13:AY13) -> 6 | BB13: =BA13/AZ11*100 -> 54.545455 | BC13: =IFERROR(IF(BB13<AO13,"Perbaiakan",IF(BB13>=AO13,"Pengayaan","")),"") -> Perbaiakan | BP13: =SUM(BE13:BN13) -> 0 | BQ13: =BP13/BO11*100 -> 0 | BR13: =IFERROR(IF(BQ13<BD13,"Perbaiakan",IF(BQ13>=BD13,"Pengayaan","")),"") -> Pengayaan
A14: 3 | B14: 3164040852 / 232401003 | C14: BAYU MAULANA. | F14: 70 | G14: 2 | H14: 0 | I14: 2 | J14: 2 | K14: 2 | R14: =SUM(G14:P14) -> 8 | S14: =R14/Q11*100 -> 80 | T14: =IFERROR(IF(S14<F14,"Perbaikan",IF(S14>=F14,"Pengayaan","")),"") -> Pengayaan | U14: 80 | V14: 80 | W14: Tuntas | AC14: Pengayaan | AD14: 80 | AE14: 80 | AF14: Tuntas | AG14: Pengayaan | AH14: 80 | AI14: 80 | AJ14: Tuntas | BA14: =SUM(AP14:AY14) -> 0 | BB14: =BA14/AZ11*100 -> 0 | BC14: =IFERROR(IF(BB14<AO14,"Perbaiakan",IF(BB14>=AO14,"Pengayaan","")),"") -> Pengayaan | BP14: =SUM(BE14:BN14) -> 0 | BQ14: =BP14/BO11*100 -> 0 | BR14: =IFERROR(IF(BQ14<BD14,"Perbaiakan",IF(BQ14>=BD14,"Pengayaan","")),"") -> Pengayaan
A15: 4 | B15: 0164553047 / 232401004 | C15: BELLA SOPYANA PUTRI | F15: 70 | G15: 2 | H15: 2 | I15: 2 | J15: 0 | K15: 2 | R15: =SUM(G15:P15) -> 8 | S15: =R15/Q11*100 -> 80 | T15: =IFERROR(IF(S15<F15,"Perbaiakan",IF(S15>=F15,"Pengayaan","")),"") -> Pengayaan | U15: 80 | V15: 80 | W15: Tuntas | AC15: Pengayaan | AD15: 80 | AE15: 80 | AF15: Tuntas | AG15: Pengayaan | AH15: 100 | AI15: 100 | AJ15: Tuntas | BA15: =SUM(AP15:AY15) -> 0 | BB15: =BA15/AZ11*100 -> 0 | BC15: =IFERROR(IF(BB15<AO15,"Perbaiakan",IF(BB15>=AO15,"Pengayaan","")),"") -> Pengayaan | BP15: =SUM(BE15:BN15) -> 0 | BQ15: =BP15/BO11*100 -> 0 | BR15: =IFERROR(IF(BQ15<BD15,"Perbaiakan",IF(BQ15>=BD15,"Pengayaan","")),"") -> Pengayaan
A16: 5 | B16: 3168177700 / 232401006 | C16: DAVA ABYAN SOFA | F16: 70 | G16: 0 | H16: 0 | I16: 2 | J16: 2 | K16: 0 | R16: =SUM(G16:P16) -> 4 | S16: =R16/Q11*100 -> 40 | T16: =IFERROR(IF(S16<F16,"Perbaikan",IF(S16>=F16,"Pengayaan","")),"") -> Perbaikan | U16: 40 | V16: 70 | W16: Tuntas | AC16: Pengayaan | AD16: 80 | AE16: 80 | AF16: Tuntas | AG16: Perbaikan | AH16: 60 | AI16: 70 | AJ16: Tuntas | BA16: =SUM(AP16:AY16) -> 0 | BB16: =BA16/AZ11*100 -> 0 | BC16: =IFERROR(IF(BB16<AO16,"Perbaiakan",IF(BB16>=AO16,"Pengayaan","")),"") -> Pengayaan | BP16: =SUM(BE16:BN16) -> 0 | BQ16: =BP16/BO11*100 -> 0 | BR16: =IFERROR(IF(BQ16<BD16,"Perbaiakan",IF(BQ16>=BD16,"Pengayaan","")),"") -> Pengayaan
A17: 6 | B17: 3163539725 / 232401007 | C17: ELVIRA ZAHRA KHAERUNNISA | F17: 70 | G17: 2 | H17: 2 | I17: 2 | J17: 2 | K17: 0 | R17: =SUM(G17:P17) -> 8 | S17: =R17/Q11*100 -> 80 | T17: =IFERROR(IF(S17<F17,"Perbaiakan",IF(S17>=F17,"Pengayaan","")),"") -> Pengayaan | U17: 80 | V17: 80 | W17: Tuntas | AC17: Perbaikan | AD17: 60 | AE17: 70 | AF17: Tuntas | AG17: Pengayaan | AH17: 80 | AI17: 80 | AJ17: Tuntas | BA17: =SUM(AP17:AY17) -> 0 | BB17: =BA17/AZ11*100 -> 0 | BC17: =IFERROR(IF(BB17<AO17,"Perbaiakan",IF(BB17>=AO17,"Pengayaan","")),"") -> Pengayaan | BP17: =SUM(BE17:BN17) -> 0 | BQ17: =BP17/BO11*100 -> 0 | BR17: =IFERROR(IF(BQ17<BD17,"Perbaiakan",IF(BQ17>=BD17,"Pengayaan","")),"") -> Pengayaan
A18: 7 | B18: 0179214781 / 232401008 | C18: EVRINA MAYSHA. | F18: 70 | G18: 2 | H18: 2 | I18: 2 | J18: 2 | K18: 0 | R18: =SUM(G18:P18) -> 8 | S18: =R18/Q11*100 -> 80 | T18: =IFERROR(IF(S18<F18,"Perbaiakan",IF(S18>=F18,"Pengayaan","")),"") -> Pengayaan | U18: 80 | V18: 80 | W18: Tuntas | AC18: Pengayaan | AD18: 80 | AE18: 80 | AF18: Tuntas | AG18: Pengayaan | AH18: 80 | AI18: 80 | AJ18: Tuntas | BA18: =SUM(AP18:AY18) -> 0 | BB18: =BA18/AZ11*100 -> 0 | BC18: =IFERROR(IF(BB18<AO18,"Perbaiakan",IF(BB18>=AO18,"Pengayaan","")),"") -> Pengayaan | BP18: =SUM(BE18:BN18) -> 0 | BQ18: =BP18/BO11*100 -> 0 | BR18: =IFERROR(IF(BQ18<BD18,"Perbaiakan",IF(BQ18>=BD18,"Pengayaan","")),"") -> Pengayaan
A19: 8 | B19: 3172453746 / 232401009 | C19: GALUH UWAIS AL QARNI | F19: 70 | G19: 2 | H19: 2 | I19: 2 | J19: 2 | K19: 2 | R19: =SUM(G19:P19) -> 10 | S19: =R19/Q11*100 -> 100 | T19: =IFERROR(IF(S19<F19,"Perbaiakan",IF(S19>=F19,"Pengayaan","")),"") -> Pengayaan | U19: 100 | V19: 100 | W19: Tuntas | AC19: Pengayaan | AD19: 80 | AE19: 80 | AF19: Tuntas | AG19: Pengayaan | AH19: 80 | AI19: 80 | AJ19: Tuntas | BA19: =SUM(AP19:AY19) -> 0 | BB19: =BA19/AZ11*100 -> 0 | BC19: =IFERROR(IF(BB19<AO19,"Perbaiakan",IF(BB19>=AO19,"Pengayaan","")),"") -> Pengayaan | BP19: =SUM(BE19:BN19) -> 0 | BQ19: =BP19/BO11*100 -> 0 | BR19: =IFERROR(IF(BQ19<BD19,"Perbaiakan",IF(BQ19>=BD19,"Pengayaan","")),"") -> Pengayaan
A20: 9 | B20: 3152261267 / 232401010 | C20: HAMZIDAN PRANADJA | F20: 70 | G20: 2 | H20: 2 | I20: 2 | J20: 0 | K20: 2 | R20: =SUM(G20:P20) -> 8 | S20: =R20/Q11*100 -> 80 | T20: =IFERROR(IF(S20<F20,"Perbaiakan",IF(S20>=F20,"Pengayaan","")),"") -> Pengayaan | U20: 80 | V20: 80 | W20: Tuntas | AC20: Pengayaan | AD20: 80 | AE20: 80 | AF20: Tuntas | AG20: Pengayaan | AH20: 80 | AI20: 80 | AJ20: Tuntas | BA20: =SUM(AP20:AY20) -> 0 | BB20: =BA20/AZ11*100 -> 0 | BC20: =IFERROR(IF(BB20<AO20,"Perbaiakan",IF(BB20>=AO20,"Pengayaan","")),"") -> Pengayaan | BP20: =SUM(BE20:BN20) -> 0 | BQ20: =BP20/BO11*100 -> 0 | BR20: =IFERROR(IF(BQ20<BD20,"Perbaiakan",IF(BQ20>=BD20,"Pengayaan","")),"") -> Pengayaan
A21: 10 | B21: 3160050189 / 232401011 | C21: HANDI PADILAH | F21: 70 | G21: 0 | H21: 0 | I21: 2 | J21: 0 | K21: 0 | R21: =SUM(G21:P21) -> 2 | S21: =R21/Q11*100 -> 20 | T21: =IFERROR(IF(S21<F21,"Perbaikan",IF(S21>=F21,"Pengayaan","")),"") -> Perbaikan | U21: 20 | V21: 70 | W21: Tuntas | AC21: Perbaikan | AD21: 0 | AE21: 70 | AF21: Tuntas | AG21: Perbaikan | AH21: 0 | AI21: 70 | AJ21: Tuntas | BA21: =SUM(AP21:AY21) -> 0 | BB21: =BA21/AZ11*100 -> 0 | BC21: =IFERROR(IF(BB21<AO21,"Perbaiakan",IF(BB21>=AO21,"Pengayaan","")),"") -> Pengayaan | BP21: =SUM(BE21:BN21) -> 0 | BQ21: =BP21/BO11*100 -> 0 | BR21: =IFERROR(IF(BQ21<BD21,"Perbaiakan",IF(BQ21>=BD21,"Pengayaan","")),"") -> Pengayaan
A22: 11 | B22: 3161520488 / 232401012 | C22: IBNU FAUZAN | F22: 70 | G22: 0 | H22: 0 | I22: 2 | J22: 2 | K22: 0 | R22: =SUM(G22:P22) -> 4 | S22: =R22/Q11*100 -> 40 | T22: =IFERROR(IF(S22<F22,"Perbaikan",IF(S22>=F22,"Pengayaan","")),"") -> Perbaikan | U22: 40 | V22: 70 | W22: Tuntas | AC22: Perbaikan | AD22: 60 | AE22: 70 | AF22: Tuntas | AG22: Perbaikan | AH22: 60 | AI22: 70 | AJ22: Tuntas | BA22: =SUM(AP22:AY22) -> 0 | BB22: =BA22/AZ11*100 -> 0 | BC22: =IFERROR(IF(BB22<AO22,"Perbaiakan",IF(BB22>=AO22,"Pengayaan","")),"") -> Pengayaan | BP22: =SUM(BE22:BN22) -> 0 | BQ22: =BP22/BO11*100 -> 0 | BR22: =IFERROR(IF(BQ22<BD22,"Perbaiakan",IF(BQ22>=BD22,"Pengayaan","")),"") -> Pengayaan
A23: 12 | B23: 3173125719 / 232401013 | C23: INTAN NADIN HANIFAH | F23: 70 | G23: 2 | H23: 0 | I23: 0 | J23: 2 | K23: 2 | R23: =SUM(G23:P23) -> 6 | S23: =R23/Q11*100 -> 60 | T23: =IFERROR(IF(S23<F23,"Perbaikan",IF(S23>=F23,"Pengayaan","")),"") -> Perbaikan | U23: 60 | V23: 70 | W23: Tuntas | AC23: Perbaikan | AD23: 40 | AE23: 70 | AF23: Tuntas | AG23: Pengayaan | AH23: 100 | AI23: 100 | AJ23: Tuntas | BA23: =SUM(AP23:AY23) -> 0 | BB23: =BA23/AZ11*100 -> 0 | BC23: =IFERROR(IF(BB23<AO23,"Perbaiakan",IF(BB23>=AO23,"Pengayaan","")),"") -> Pengayaan | BP23: =SUM(BE23:BN23) -> 0 | BQ23: =BP23/BO11*100 -> 0 | BR23: =IFERROR(IF(BQ23<BD23,"Perbaiakan",IF(BQ23>=BD23,"Pengayaan","")),"") -> Pengayaan
A24: 13 | B24: 3168397502 / 232401014 | C24: KAHFI | F24: 70 | G24: 2 | H24: 2 | I24: 2 | J24: 2 | K24: 2 | R24: =SUM(G24:K24) -> 10 | S24: =R24/Q11*100 -> 100 | T24: =IFERROR(IF(S24<F24,"Perbaiakan",IF(S24>=F24,"Pengayaan","")),"") -> Pengayaan | U24: 100 | V24: 100 | W24: Tuntas | AC24: Pengayaan | AD24: 80 | AE24: 80 | AF24: Tuntas | AG24: Pengayaan | AH24: 80 | AI24: 80 | AJ24: Tuntas | BA24: =SUM(AP24:AY24) -> 0 | BB24: =BA24/AZ11*100 -> 0 | BC24: =IFERROR(IF(BB24<AO24,"Perbaiakan",IF(BB24>=AO24,"Pengayaan","")),"") -> Pengayaan | BP24: =SUM(BE24:BN24) -> 0 | BQ24: =BP24/BO11*100 -> 0 | BR24: =IFERROR(IF(BQ24<BD24,"Perbaiakan",IF(BQ24>=BD24,"Pengayaan","")),"") -> Pengayaan
A25: 14 | B25: 3168012888 / 232401016 | C25: KAYSAN RAJENDRA | F25: 70 | G25: 2 | H25: 2 | I25: 2 | J25: 2 | K25: 2 | R25: =SUM(G25:P25) -> 10 | S25: =R25/Q11*100 -> 100 | T25: =IFERROR(IF(S25<F25,"Perbaiakan",IF(S25>=F25,"Pengayaan","")),"") -> Pengayaan | U25: 100 | V25: 100 | W25: Tuntas | AC25: Pengayaan | AD25: 80 | AE25: 80 | AF25: Tuntas | AG25: Pengayaan | AH25: 100 | AI25: 100 | AJ25: Tuntas | BA25: =SUM(AP25:AY25) -> 0 | BB25: =BA25/AZ11*100 -> 0 | BC25: =IFERROR(IF(BB25<AO25,"Perbaiakan",IF(BB25>=AO25,"Pengayaan","")),"") -> Pengayaan | BP25: =SUM(BE25:BN25) -> 0 | BQ25: =BP25/BO11*100 -> 0 | BR25: =IFERROR(IF(BQ25<BD25,"Perbaiakan",IF(BQ25>=BD25,"Pengayaan","")),"") -> Pengayaan
A26: 15 | B26: 3173642710 / 232401017 | C26: MEITA PRABA NURRIZKI | F26: 70 | G26: 0 | H26: 2 | I26: 2 | J26: 2 | K26: 2 | R26: =SUM(G26:P26) -> 8 | S26: =R26/Q11*100 -> 80 | T26: =IFERROR(IF(S26<F26,"Perbaiakan",IF(S26>=F26,"Pengayaan","")),"") -> Pengayaan | U26: 80 | V26: 80 | W26: Tuntas | AC26: Perbaikan | AD26: 60 | AE26: 70 | AF26: Tuntas | AG26: Pengayaan | AH26: 80 | AI26: 80 | AJ26: Tuntas | BA26: =SUM(AP26:AY26) -> 0 | BB26: =BA26/AZ11*100 -> 0 | BC26: =IFERROR(IF(BB26<AO26,"Perbaiakan",IF(BB26>=AO26,"Pengayaan","")),"") -> Pengayaan | BP26: =SUM(BE26:BN26) -> 0 | BQ26: =BP26/BO11*100 -> 0 | BR26: =IFERROR(IF(BQ26<BD26,"Perbaiakan",IF(BQ26>=BD26,"Pengayaan","")),"") -> Pengayaan
A27: 16 | B27: 3174719695 / 232401018 | C27: MILKA NURUL FADHILAH | F27: 70 | G27: 0 | H27: 0 | I27: 0 | J27: 2 | K27: 2 | R27: =SUM(G27:P27) -> 4 | S27: =R27/Q11*100 -> 40 | T27: =IFERROR(IF(S27<F27,"Perbaikan",IF(S27>=F27,"Pengayaan","")),"") -> Perbaikan | U27: 40 | V27: 70 | W27: Tuntas | AC27: Perbaikan | AD27: 60 | AE27: 70 | AF27: Tuntas | AG27: Pengayaan | AH27: 100 | AI27: 100 | AJ27: Tuntas | BA27: =SUM(AP27:AY27) -> 0 | BB27: =BA27/AZ11*100 -> 0 | BC27: =IFERROR(IF(BB27<AO27,"Perbaiakan",IF(BB27>=AO27,"Pengayaan","")),"") -> Pengayaan | BP27: =SUM(BE27:BN27) -> 0 | BQ27: =BP27/BO11*100 -> 0 | BR27: =IFERROR(IF(BQ27<BD27,"Perbaiakan",IF(BQ27>=BD27,"Pengayaan","")),"") -> Pengayaan
A28: 17 | B28: 3170243842 / 232401019 | C28: MIRA SINTIAWATI | F28: 70 | G28: 2 | H28: 2 | I28: 2 | J28: 2 | K28: 2 | R28: =SUM(G28:P28) -> 10 | S28: =R28/Q11*100 -> 100 | T28: =IFERROR(IF(S28<F28,"Perbaiakan",IF(S28>=F28,"Pengayaan","")),"") -> Pengayaan | U28: 100 | V28: 100 | W28: Tuntas | AC28: Perbaikan | AD28: 60 | AE28: 70 | AF28: Tuntas | AG28: Pengayaan | AH28: 100 | AI28: 100 | AJ28: Tuntas | BA28: =SUM(AP28:AY28) -> 0 | BB28: =BA28/AZ11*100 -> 0 | BC28: =IFERROR(IF(BB28<AO28,"Perbaiakan",IF(BB28>=AO28,"Pengayaan","")),"") -> Pengayaan | BP28: =SUM(BE28:BN28) -> 0 | BQ28: =BP28/BO11*100 -> 0 | BR28: =IFERROR(IF(BQ28<BD28,"Perbaiakan",IF(BQ28>=BD28,"Pengayaan","")),"") -> Pengayaan
A29: 18 | B29: 3160808194 / 232401020 | C29: MUHAMMAD HADIQ AL FARUQ | F29: 70 | G29: 0 | H29: 2 | I29: 2 | J29: 2 | K29: 0 | R29: =SUM(G29:P29) -> 6 | S29: =R29/Q11*100 -> 60 | T29: =IFERROR(IF(S29<F29,"Perbaikan",IF(S29>=F29,"Pengayaan","")),"") -> Perbaikan | U29: 60 | V29: 70 | W29: Tuntas | AC29: Pengayaan | AD29: 80 | AE29: 80 | AF29: Tuntas | AG29: Pengayaan | AH29: 100 | AI29: 100 | AJ29: Tuntas | BA29: =SUM(AP29:AY29) -> 0 | BB29: =BA29/AZ11*100 -> 0 | BC29: =IFERROR(IF(BB29<AO29,"Perbaiakan",IF(BB29>=AO29,"Pengayaan","")),"") -> Pengayaan | BP29: =SUM(BE29:BN29) -> 0 | BQ29: =BP29/BO11*100 -> 0 | BR29: =IFERROR(IF(BQ29<BD29,"Perbaiakan",IF(BQ29>=BD29,"Pengayaan","")),"") -> Pengayaan
A30: 19 | B30: 3162061937 / 232401021 | C30: MUTIA ALIFA AZZAHRA | F30: 70 | G30: 0 | H30: 0 | I30: 2 | J30: 2 | K30: 2 | R30: =SUM(G30:P30) -> 6 | S30: =R30/Q11*100 -> 60 | T30: =IFERROR(IF(S30<F30,"Perbaikan",IF(S30>=F30,"Pengayaan","")),"") -> Perbaikan | U30: 60 | V30: 70 | W30: Tuntas | AC30: Pengayaan | AD30: 80 | AE30: 80 | AF30: Tuntas | AG30: Pengayaan | AH30: 100 | AI30: 100 | AJ30: Tuntas | BA30: =SUM(AP30:AY30) -> 0 | BB30: =BA30/AZ11*100 -> 0 | BC30: =IFERROR(IF(BB30<AO30,"Perbaiakan",IF(BB30>=AO30,"Pengayaan","")),"") -> Pengayaan | BP30: =SUM(BE30:BN30) -> 0 | BQ30: =BP30/BO11*100 -> 0 | BR30: =IFERROR(IF(BQ30<BD30,"Perbaiakan",IF(BQ30>=BD30,"Pengayaan","")),"") -> Pengayaan
A31: 20 | B31: 3173955890 / 232401022 | C31: MUTIA PUTRI NURAZIZAH | F31: 70 | G31: 0 | H31: 2 | I31: 2 | J31: 2 | K31: 2 | R31: =SUM(G31:P31) -> 8 | S31: =R31/Q11*100 -> 80 | T31: =IFERROR(IF(S31<F31,"Perbaiakan",IF(S31>=F31,"Pengayaan","")),"") -> Pengayaan | U31: 80 | V31: 80 | W31: Tuntas | AC31: Perbaikan | AD31: 60 | AE31: 70 | AF31: Tuntas | AG31: Pengayaan | AH31: 100 | AI31: 100 | AJ31: Tuntas | BA31: =SUM(AP31:AY31) -> 0 | BB31: =BA31/AZ11*100 -> 0 | BC31: =IFERROR(IF(BB31<AO31,"Perbaiakan",IF(BB31>=AO31,"Pengayaan","")),"") -> Pengayaan | BP31: =SUM(BE31:BN31) -> 0 | BQ31: =BP31/BO11*100 -> 0 | BR31: =IFERROR(IF(BQ31<BD31,"Perbaiakan",IF(BQ31>=BD31,"Pengayaan","")),"") -> Pengayaan
A32: 21 | B32: 3164171038 / 232401023 | C32: NABIL KAFIN ABIZARD | F32: 70 | G32: 2 | H32: 0 | I32: 2 | J32: 2 | K32: 2 | R32: =SUM(G32:P32) -> 8 | S32: =R32/Q11*100 -> 80 | T32: =IFERROR(IF(S32<F32,"Perbaiakan",IF(S32>=F32,"Pengayaan","")),"") -> Pengayaan | U32: 80 | V32: 80 | W32: Tuntas | AC32: Pengayaan | AD32: 100 | AE32: 100 | AF32: Tuntas | AG32: Pengayaan | AH32: 80 | AI32: 80 | AJ32: Tuntas | BA32: =SUM(AP32:AY32) -> 0 | BB32: =BA32/AZ11*100 -> 0 | BC32: =IFERROR(IF(BB32<AO32,"Perbaiakan",IF(BB32>=AO32,"Pengayaan","")),"") -> Pengayaan | BP32: =SUM(BE32:BN32) -> 0 | BQ32: =BP32/BO11*100 -> 0 | BR32: =IFERROR(IF(BQ32<BD32,"Perbaiakan",IF(BQ32>=BD32,"Pengayaan","")),"") -> Pengayaan
A33: 22 | B33: 3168619383 / 232401024 | C33: NURSILMY FAUZIYAH | F33: 70 | G33: 0 | H33: 2 | I33: 0 | J33: 0 | K33: 2 | R33: =SUM(G33:P33) -> 4 | S33: =R33/Q11*100 -> 40 | T33: =IFERROR(IF(S33<F33,"Perbaikan",IF(S33>=F33,"Pengayaan","")),"") -> Perbaikan | U33: 40 | V33: 70 | W33: Tuntas | AC33: Pengayaan | AD33: 80 | AE33: 80 | AF33: Tuntas | AG33: Pengayaan | AH33: 80 | AI33: 80 | AJ33: Tuntas | BA33: =SUM(AP33:AY33) -> 0 | BB33: =BA33/AZ11*100 -> 0 | BC33: =IFERROR(IF(BB33<AO33,"Perbaiakan",IF(BB33>=AO33,"Pengayaan","")),"") -> Pengayaan | BP33: =SUM(BE33:BN33) -> 0 | BQ33: =BP33/BO11*100 -> 0 | BR33: =IFERROR(IF(BQ33<BD33,"Perbaiakan",IF(BQ33>=BD33,"Pengayaan","")),"") -> Pengayaan
A34: 23 | B34: 3177975994 / 232401025 | C34: RAHMA AZAHRA | F34: 70 | G34: 2 | H34: 2 | I34: 2 | J34: 2 | K34: 2 | R34: =SUM(G34:P34) -> 10 | S34: =R34/Q11*100 -> 100 | T34: =IFERROR(IF(S34<F34,"Perbaiakan",IF(S34>=F34,"Pengayaan","")),"") -> Pengayaan | U34: 100 | V34: 100 | W34: Tuntas | AC34: Pengayaan | AD34: 80 | AE34: 80 | AF34: Tuntas | AG34: Pengayaan | AH34: 100 | AI34: 100 | AJ34: Tuntas | BA34: =SUM(AP34:AY34) -> 0 | BB34: =BA34/AZ11*100 -> 0 | BC34: =IFERROR(IF(BB34<AO34,"Perbaiakan",IF(BB34>=AO34,"Pengayaan","")),"") -> Pengayaan | BP34: =SUM(BE34:BN34) -> 0 | BQ34: =BP34/BO11*100 -> 0 | BR34: =IFERROR(IF(BQ34<BD34,"Perbaiakan",IF(BQ34>=BD34,"Pengayaan","")),"") -> Pengayaan
A35: 24 | B35: 3166760674 / 232401026 | C35: RIFKY NAUFAL RAMDHANI | F35: 70 | G35: 2 | H35: 2 | I35: 2 | J35: 2 | K35: 2 | R35: =SUM(G35:P35) -> 10 | S35: =R35/Q11*100 -> 100 | T35: =IFERROR(IF(S35<F35,"Perbaiakan",IF(S35>=F35,"Pengayaan","")),"") -> Pengayaan | U35: 100 | V35: 100 | W35: Tuntas | AC35: Pengayaan | AD35: 80 | AE35: 80 | AF35: Tuntas | AG35: Pengayaan | AH35: 80 | AI35: 80 | AJ35: Tuntas | BA35: =SUM(AP35:AY35) -> 0 | BB35: =BA35/AZ11*100 -> 0 | BC35: =IFERROR(IF(BB35<AO35,"Perbaiakan",IF(BB35>=AO35,"Pengayaan","")),"") -> Pengayaan | BP35: =SUM(BE35:BN35) -> 0 | BQ35: =BP35/BO11*100 -> 0 | BR35: =IFERROR(IF(BQ35<BD35,"Perbaiakan",IF(BQ35>=BD35,"Pengayaan","")),"") -> Pengayaan
A36: 25 | B36: 3170616522 / 232401027 | C36: RIFKY NIZAM RAMADANSYAH | F36: 70 | G36: 0 | H36: 0 | I36: 2 | J36: 2 | K36: 2 | R36: =SUM(G36:P36) -> 6 | S36: =R36/Q11*100 -> 60 | T36: =IFERROR(IF(S36<F36,"Perbaikan",IF(S36>=F36,"Pengayaan","")),"") -> Perbaikan | U36: 60 | V36: 70 | W36: Tuntas | AC36: Pengayaan | AD36: 80 | AE36: 80 | AF36: Tuntas | AG36: Perbaikan | AH36: 0 | AI36: 70 | AJ36: Tuntas | BA36: =SUM(AP36:AY36) -> 0 | BB36: =BA36/AZ11*100 -> 0 | BC36: =IFERROR(IF(BB36<AO36,"Perbaiakan",IF(BB36>=AO36,"Pengayaan","")),"") -> Pengayaan | BP36: =SUM(BE36:BN36) -> 0 | BQ36: =BP36/BO11*100 -> 0 | BR36: =IFERROR(IF(BQ36<BD36,"Perbaiakan",IF(BQ36>=BD36,"Pengayaan","")),"") -> Pengayaan
A37: 26 | B37: 3165120944 / 232401028 | C37: SAMSUL HADI NURU. | F37: 70 | G37: 0 | H37: 2 | I37: 2 | J37: 2 | K37: 2 | R37: =SUM(G37:P37) -> 8 | S37: =R37/Q11*100 -> 80 | T37: =IFERROR(IF(S37<F37,"Perbaiakan",IF(S37>=F37,"Pengayaan","")),"") -> Pengayaan | U37: 80 | V37: 80 | W37: Tuntas | AC37: Pengayaan | AD37: 80 | AE37: 80 | AF37: Tuntas | AG37: Pengayaan | AH37: 80 | AI37: 80 | AJ37: Tuntas | BA37: =SUM(AP37:AY37) -> 0 | BB37: =BA37/AZ11*100 -> 0 | BC37: =IFERROR(IF(BB37<AO37,"Perbaiakan",IF(BB37>=AO37,"Pengayaan","")),"") -> Pengayaan | BP37: =SUM(BE37:BN37) -> 0 | BQ37: =BP37/BO11*100 -> 0 | BR37: =IFERROR(IF(BQ37<BD37,"Perbaiakan",IF(BQ37>=BD37,"Pengayaan","")),"") -> Pengayaan
A38: 27 | B38: 3166662295 / 232401029 | C38: SHELA AULIA SUJANA | F38: 70 | G38: 2 | H38: 2 | I38: 2 | J38: 2 | K38: 0 | R38: =SUM(G38:P38) -> 8 | S38: =R38/Q11*100 -> 80 | T38: =IFERROR(IF(S38<F38,"Perbaiakan",IF(S38>=F38,"Pengayaan","")),"") -> Pengayaan | U38: 80 | V38: 80 | W38: Tuntas | AC38: Pengayaan | AD38: 80 | AE38: 80 | AF38: Tuntas | AG38: Pengayaan | AH38: 80 | AI38: 80 | AJ38: Tuntas | BA38: =SUM(AP38:AY38) -> 0 | BB38: =BA38/AZ11*100 -> 0 | BC38: =IFERROR(IF(BB38<AO38,"Perbaiakan",IF(BB38>=AO38,"Pengayaan","")),"") -> Pengayaan | BP38: =SUM(BE38:BN38) -> 0 | BQ38: =BP38/BO11*100 -> 0 | BR38: =IFERROR(IF(BQ38<BD38,"Perbaiakan",IF(BQ38>=BD38,"Pengayaan","")),"") -> Pengayaan
A39: 28 | B39: 3171885467 / 232401030 | C39: SIFA FEBRIANA ZAHIRA. | F39: 70 | G39: 0 | H39: 2 | I39: 2 | J39: 2 | K39: 2 | R39: =SUM(G39:P39) -> 8 | S39: =R39/Q11*100 -> 80 | T39: =IFERROR(IF(S39<F39,"Perbaiakan",IF(S39>=F39,"Pengayaan","")),"") -> Pengayaan | U39: 80 | V39: 80 | W39: Tuntas | AC39: Pengayaan | AD39: 80 | AE39: 80 | AF39: Tuntas | AG39: Pengayaan | AH39: 80 | AI39: 80 | AJ39: Tuntas | BA39: =SUM(AP39:AY39) -> 0 | BB39: =BA39/AZ11*100 -> 0 | BC39: =IFERROR(IF(BB39<AO39,"Perbaiakan",IF(BB39>=AO39,"Pengayaan","")),"") -> Pengayaan | BP39: =SUM(BE39:BN39) -> 0 | BQ39: =BP39/BO11*100 -> 0 | BR39: =IFERROR(IF(BQ39<BD39,"Perbaiakan",IF(BQ39>=BD39,"Pengayaan","")),"") -> Pengayaan
A40: 29 | B40: 3160399284 / 232401042 | C40: SIVA SURYANI | F40: 70 | G40: 0 | H40: 2 | I40: 2 | J40: 2 | K40: 2 | R40: =SUM(G40:P40) -> 8 | S40: =R40/Q11*100 -> 80 | T40: =IFERROR(IF(S40<F40,"Perbaiakan",IF(S40>=F40,"Pengayaan","")),"") -> Pengayaan | U40: 80 | V40: 80 | W40: Tuntas | AC40: Pengayaan | AD40: 80 | AE40: 80 | AF40: Tuntas | AG40: Pengayaan | AH40: 80 | AI40: 80 | AJ40: Tuntas | BA40: =SUM(AP40:AY40) -> 0 | BB40: =BA40/AZ11*100 -> 0 | BC40: =IFERROR(IF(BB40<AO40,"Perbaiakan",IF(BB40>=AO40,"Pengayaan","")),"") -> Pengayaan | BP40: =SUM(BE40:BN40) -> 0 | BQ40: =BP40/BO11*100 -> 0 | BR40: =IFERROR(IF(BQ40<BD40,"Perbaiakan",IF(BQ40>=BD40,"Pengayaan","")),"") -> Pengayaan
A41: 30 | B41: 3163684371 / 232401031 | C41: TEDI I AZRY KURNIA | F41: 70 | G41: 2 | H41: 2 | I41: 2 | J41: 2 | K41: 2 | R41: =SUM(G41:P41) -> 10 | S41: =R41/Q11*100 -> 100 | T41: =IFERROR(IF(S41<F41,"Perbaiakan",IF(S41>=F41,"Pengayaan","")),"") -> Pengayaan | U41: 100 | V41: 100 | W41: Tuntas | AC41: Pengayaan | AD41: 100 | AE41: 100 | AF41: Tuntas | AG41: Pengayaan | AH41: 80 | AI41: 80 | AJ41: Tuntas | BA41: =SUM(AP41:AY41) -> 0 | BB41: =BA41/AZ11*100 -> 0 | BC41: =IFERROR(IF(BB41<AO41,"Perbaiakan",IF(BB41>=AO41,"Pengayaan","")),"") -> Pengayaan | BP41: =SUM(BE41:BN41) -> 0 | BQ41: =BP41/BO11*100 -> 0 | BR41: =IFERROR(IF(BQ41<BD41,"Perbaiakan",IF(BQ41>=BD41,"Pengayaan","")),"") -> Pengayaan
A42: 31 | B42: 3165625220 / 232401032 | C42: TRISTAN SAKHA PERMANA | F42: 70 | G42: 0 | H42: 0 | I42: 2 | J42: 2 | K42: 2 | R42: =SUM(G42:P42) -> 6 | S42: =R42/Q11*100 -> 60 | T42: =IFERROR(IF(S42<F42,"Perbaikan",IF(S42>=F42,"Pengayaan","")),"") -> Perbaikan | U42: 60 | V42: 70 | W42: Tuntas | AC42: Pengayaan | AD42: 80 | AE42: 80 | AF42: Tuntas | AG42: Pengayaan | AH42: 80 | AI42: 80 | AJ42: Tuntas | BA42: =SUM(AP42:AY42) -> 0 | BB42: =BA42/AZ11*100 -> 0 | BC42: =IFERROR(IF(BB42<AO42,"Perbaiakan",IF(BB42>=AO42,"Pengayaan","")),"") -> Pengayaan | BP42: =SUM(BE42:BN42) -> 0 | BQ42: =BP42/BO11*100 -> 0 | BR42: =IFERROR(IF(BQ42<BD42,"Perbaiakan",IF(BQ42>=BD42,"Pengayaan","")),"") -> Pengayaan
...

Sheet Sumatif Lingkup Materi (2)
D1: ANALISIS HASIL ASESMEN SUMATIF LINGKUP MATERI
D2: ='oke Lingk. 1'!G2 -> TAHUN AJARAN 2025/2026
E4: Kelas / Semester | K4: : | L4: I/2
E5: Mata Pelajaran | K5: : | L5: ='oke Lingk. 1'!N5 -> PAI dan Budi Pekerti
E6: TP 1 | K6: :
A8: NO | B8: NIS | C8: NAMA SISWA | D8: Nomor Soal
D9: Nilai Minimal | E9: 1 | F9: 2 | G9: 3 | H9: 4 | I9: 5 | J9: 6 | K9: 7 | L9: 8 | M9: 9 | N9: 10 | O9: 11 | P9: 12 | Q9: 13 | R9: 14 | S9: 15 | U9: Skor | V9: Nilai Akhir | W9: Tindak Lanjut
E10: Skor Maksimal Tiap Soal
C11: Skor Maksimal | E11: 1 | F11: 1 | G11: 1 | H11: 1 | I11: 1 | J11: 1 | K11: 1 | L11: 1 | M11: 1 | N11: 1 | O11: 2 | P11: 2 | Q11: 2 | R11: 2 | S11: 2 | T11: =SUM(E11:S11) -> 20
A12: 1 | B12: 3163415080 / 232401001 | C12: ARGA SEFERAGIC | D12: 70 | E12: 1 | F12: 1 | G12: 1 | H12: 1 | I12: 1 | J12: 0 | K12: 1 | L12: 1 | M12: 0 | N12: 1 | O12: 2 | P12: 2 | Q12: 2 | R12: 1 | S12: 1 | U12: =SUM(E12:S12) -> 16 | V12: =U12/T11*100 -> 80 | W12: =IFERROR(IF(V12<D12,"Perlu mengulang beberapa Tujuan Pembelajaran dalam Mata Pelajarann ",IF(V12>=D12,"Dinyatakan tuntas untuk seluruh Tujuan Pembelajaran dalam Mata Pelajaran ","")),"") &L5 -> Dinyatakan tuntas untuk seluruh Tujuan Pembelajaran dalam Mata Pelajaran PAI dan Budi Pekerti
A13: 2 | B13: 3161997134 / 232401002 | C13: ARKHA ARDANA PUTRA | D13: 70 | E13: 1 | F13: 1 | G13: 1 | H13: 1 | I13: 1 | J13: 1 | K13: 1 | L13: 1 | M13: 0 | N13: 1 | O13: 2 | P13: 2 | Q13: 2 | R13: 2 | S13: 1 | U13: =SUM(E13:S13) -> 18 | V13: =U13/T11*100 -> 90 | W13: =IFERROR(IF(V13<D13,"Perlu mengulang beberapa Tujuan Pembelajaran dalam Mata Pelajarann ",IF(V13>=D13,"Dinyatakan tuntas untuk seluruh Tujuan Pembelajaran dalam Mata Pelajaran ","")),"") &L5 -> Dinyatakan tuntas untuk seluruh Tujuan Pembelajaran dalam Mata Pelajaran PAI dan Budi Pekerti
A14: 3 | B14: 3164040852 / 232401003 | C14: BAYU MAULANA. | D14: 70 | E14: 1 | F14: 1 | G14: 1 | H14: 1 | I14: 1 | J14: 1 | K14: 1 | L14: 1 | M14: 0 | N14: 0 | O14: 2 | P14: 2 | Q14: 2 | R14: 2 | S14: 1 | U14: =SUM(E14:S14) -> 17 | V14: =U14/T11*100 -> 85 | W14: =IFERROR(IF(V14<D14,"Perlu mengulang beberapa Tujuan Pembelajaran dalam Mata Pelajarann ",IF(V14>=D14,"Dinyatakan tuntas untuk seluruh Tujuan Pembelajaran dalam Mata Pelajaran ","")),"") &L5 -> Dinyatakan tuntas untuk seluruh Tujuan Pembelajaran dalam Mata Pelajaran PAI dan Budi Pekerti
A15: 4 | B15: 0164553047 / 232401004 | C15: Bella Sopyana Putri | D15: 70 | E15: 1 | F15: 1 | G15: 0 | H15: 1 | I15: 1 | J15: 0 | K15: 1 | L15: 1 | M15: 1 | N15: 1 | O15: 2 | P15: 2 | Q15: 2 | R15: 2 | S15: 2 | U15: =SUM(E15:S15) -> 18 | V15: =U15/T11*100 -> 90 | W15: =IFERROR(IF(V15<D15,"Perlu mengulang beberapa Tujuan Pembelajaran dalam Mata Pelajarann ",IF(V15>=D15,"Dinyatakan tuntas untuk seluruh Tujuan Pembelajaran dalam Mata Pelajaran ","")),"") &L5 -> Dinyatakan tuntas untuk seluruh Tujuan Pembelajaran dalam Mata Pelajaran PAI dan Budi Pekerti
A16: 5 | B16: 3171073614 / 232401005 | C16: CAKRAWIGUNA. | D16: 70 | E16: 1 | F16: 1 | G16: 1 | H16: 1 | I16: 1 | J16: 1 | K16: 1 | L16: 1 | M16: 1 | N16: 1 | O16: 1 | P16: 0 | Q16: 0 | R16: 0 | S16: 0 | U16: =SUM(E16:S16) -> 11 | V16: =U16/T11*100 -> 55 | W16: =IFERROR(IF(V16<D16,"Perlu mengulang beberapa Tujuan Pembelajaran dalam Mata Pelajarann ",IF(V16>=D16,"Dinyatakan tuntas untuk seluruh Tujuan Pembelajaran dalam Mata Pelajaran ","")),"") &L5 -> Perlu mengulang beberapa Tujuan Pembelajaran dalam Mata Pelajarann PAI dan Budi Pekerti
A17: 6 | B17: 3168177700 / 232401006 | C17: DAVA ABYAN SOFA | D17: 70 | E17: 1 | F17: 1 | G17: 1 | H17: 1 | I17: 1 | J17: 1 | K17: 1 | L17: 1 | M17: 0 | N17: 0 | O17: 2 | P17: 2 | Q17: 2 | R17: 2 | S17: 2 | U17: =SUM(E17:S17) -> 18 | V17: =U17/T11*100 -> 90 | W17: =IFERROR(IF(V17<D17,"Perlu mengulang beberapa Tujuan Pembelajaran dalam Mata Pelajarann ",IF(V17>=D17,"Dinyatakan tuntas untuk seluruh Tujuan Pembelajaran dalam Mata Pelajaran ","")),"") &L5 -> Dinyatakan tuntas untuk seluruh Tujuan Pembelajaran dalam Mata Pelajaran PAI dan Budi Pekerti
A18: 7 | B18: 3163539725 / 232401007 | C18: ELVIRA ZAHRA KHAERUNNISA | D18: 70 | E18: 1 | F18: 1 | G18: 0 | H18: 0 | I18: 0 | J18: 0 | K18: 1 | L18: 1 | M18: 0 | N18: 1 | O18: 2 | P18: 2 | Q18: 2 | R18: 2 | S18: 2 | U18: =SUM(E18:S18) -> 15 | V18: =U18/T11*100 -> 75 | W18: =IFERROR(IF(V18<D18,"Perlu mengulang beberapa Tujuan Pembelajaran dalam Mata Pelajarann ",IF(V18>=D18,"Dinyatakan tuntas untuk seluruh Tujuan Pembelajaran dalam Mata Pelajaran ","")),"") &L5 -> Dinyatakan tuntas untuk seluruh Tujuan Pembelajaran dalam Mata Pelajaran PAI dan Budi Pekerti
A19: 8 | B19: 0179214781 / 232401008 | C19: EVRINA MAYSHA. | D19: 70 | E19: 1 | F19: 1 | G19: 1 | H19: 0 | I19: 0 | J19: 0 | K19: 1 | L19: 1 | M19: 1 | N19: 1 | O19: 2 | P19: 2 | Q19: 2 | R19: 1 | S19: 1 | U19: =SUM(E19:S19) -> 15 | V19: =U19/T11*100 -> 75 | W19: =IFERROR(IF(V19<D19,"Perlu mengulang beberapa Tujuan Pembelajaran dalam Mata Pelajarann ",IF(V19>=D19,"Dinyatakan tuntas untuk seluruh Tujuan Pembelajaran dalam Mata Pelajaran ","")),"") &L5 -> Dinyatakan tuntas untuk seluruh Tujuan Pembelajaran dalam Mata Pelajaran PAI dan Budi Pekerti
A20: 9 | B20: 3172453746 / 232401009 | C20: GALUH UWAIS AL QARNI | D20: 70 | E20: 0 | F20: 1 | G20: 1 | H20: 1 | I20: 1 | J20: 1 | K20: 0 | L20: 1 | M20: 0 | N20: 1 | O20: 2 | P20: 2 | Q20: 2 | R20: 2 | S20: 2 | U20: =SUM(E20:S20) -> 17 | V20: =U20/T11*100 -> 85 | W20: =IFERROR(IF(V20<D20,"Perlu mengulang beberapa Tujuan Pembelajaran dalam Mata Pelajarann ",IF(V20>=D20,"Dinyatakan tuntas untuk seluruh Tujuan Pembelajaran dalam Mata Pelajaran ","")),"") &L5 -> Dinyatakan tuntas untuk seluruh Tujuan Pembelajaran dalam Mata Pelajaran PAI dan Budi Pekerti
A21: 10 | B21: 3152261267 / 232401010 | C21: HAMZIDAN PRANADJA | D21: 70 | E21: 1 | F21: 1 | G21: 1 | H21: 1 | I21: 1 | J21: 0 | K21: 0 | L21: 1 | M21: 0 | N21: 1 | O21: 2 | P21: 2 | Q21: 1 | R21: 1 | S21: 1 | U21: =SUM(E21:S21) -> 14 | V21: =U21/T11*100 -> 70 | W21: =IFERROR(IF(V21<D21,"Perlu mengulang beberapa Tujuan Pembelajaran dalam Mata Pelajarann ",IF(V21>=D21,"Dinyatakan tuntas untuk seluruh Tujuan Pembelajaran dalam Mata Pelajaran ","")),"") &L5 -> Dinyatakan tuntas untuk seluruh Tujuan Pembelajaran dalam Mata Pelajaran PAI dan Budi Pekerti
A22: 11 | B22: 3160050189 / 232401011 | C22: HANDI PADILAH | D22: 70 | E22: 0 | F22: 1 | G22: 0 | H22: 1 | I22: 0 | J22: 1 | K22: 0 | L22: 0 | M22: 0 | N22: 0 | O22: 2 | P22: 2 | Q22: 2 | R22: 1 | S22: 0 | U22: =SUM(E22:S22) -> 10 | V22: =U22/T11*100 -> 50 | W22: =IFERROR(IF(V22<D22,"Perlu mengulang beberapa Tujuan Pembelajaran dalam Mata Pelajarann ",IF(V22>=D22,"Dinyatakan tuntas untuk seluruh Tujuan Pembelajaran dalam Mata Pelajaran ","")),"") &L5 -> Perlu mengulang beberapa Tujuan Pembelajaran dalam Mata Pelajarann PAI dan Budi Pekerti
A23: 12 | B23: 3161520488 / 232401012 | C23: IBNU FAUZAN | D23: 70 | E23: 1 | F23: 1 | G23: 1 | H23: 1 | I23: 1 | J23: 0 | K23: 0 | L23: 1 | M23: 0 | N23: 1 | O23: 2 | P23: 2 | Q23: 2 | R23: 2 | S23: 2 | U23: =SUM(E23:S23) -> 17 | V23: =U23/T11*100 -> 85 | W23: =IFERROR(IF(V23<D23,"Perlu mengulang beberapa Tujuan Pembelajaran dalam Mata Pelajarann ",IF(V23>=D23,"Dinyatakan tuntas untuk seluruh Tujuan Pembelajaran dalam Mata Pelajaran ","")),"") &L5 -> Dinyatakan tuntas untuk seluruh Tujuan Pembelajaran dalam Mata Pelajaran PAI dan Budi Pekerti
A24: 13 | B24: 3173125719 / 232401013 | C24: INTAN NADIN HANIFAH | D24: 70 | E24: 1 | F24: 1 | G24: 1 | H24: 1 | I24: 1 | J24: 0 | K24: 1 | L24: 1 | M24: 1 | N24: 1 | O24: 2 | P24: 2 | Q24: 2 | R24: 2 | S24: 2 | U24: =SUM(E24:S24) -> 19 | V24: =U24/T11*100 -> 95 | W24: =IFERROR(IF(V24<D24,"Perlu mengulang beberapa Tujuan Pembelajaran dalam Mata Pelajarann ",IF(V24>=D24,"Dinyatakan tuntas untuk seluruh Tujuan Pembelajaran dalam Mata Pelajaran ","")),"") &L5 -> Dinyatakan tuntas untuk seluruh Tujuan Pembelajaran dalam Mata Pelajaran PAI dan Budi Pekerti
