Workbook

Sheet Kaldik Baru
B1: KALENDER PENDIDIKAN
B2: UPTD SEKOLAH DASAR NEGERI 1 SUKAMUKTI
B3: TAHUN PELAJARAN 2023 - 2024
B5: BULAN JULI 2023 | J5: BULAN AGUSTUS 2023 | R5: BULAN SEPTEMBER 2023
B6: Minggu | C6: Senin | D6: Selasa | E6: Rabu | F6: Kamis | G6: Jum'at | H6: Sabtu | J6: Minggu | K6: Senin | L6: Selasa | M6: Rabu | N6: Kamis | O6: Jum'at | P6: Sabtu | R6: Minggu | S6: Senin | T6: Selasa | U6: Rabu | V6: Kamis | W6: Jum'at | X6: Sabtu
G7: 1 | H7: 2 | K7: 1 | L7: 2 | M7: 3 | N7: 4 | O7: 5 | P7: 6 | V7: 1 | W7: 2 | X7: 3
B8: 3 | C8: 4 | D8: 5 | E8: 6 | F8: 7 | G8: 8 | H8: 9 | J8: 7 | K8: 8 | L8: 9 | M8: 10 | N8: 11 | O8: 12 | P8: 13 | R8: 4 | S8: 5 | T8: 6 | U8: 7 | V8: 8 | W8: 9 | X8: 10
B9: 10 | C9: 11 | D9: 12 | E9: 13 | F9: 14 | G9: 15 | H9: 16 | J9: 14 | K9: 15 | L9: 16 | M9: 17 | N9: 18 | O9: 19 | P9: 20 | R9: 11 | S9: 12 | T9: 13 | U9: 14 | V9: 15 | W9: 16 | X9: 17
B10: 17 | C10: 18 | D10: 19 | E10: 20 | F10: 21 | G10: 22 | H10: 23 | J10: 21 | K10: 22 | L10: 23 | M10: 24 | N10: 25 | O10: 26 | P10: 27 | R10: 18 | S10: 19 | T10: 20 | U10: 21 | V10: 22 | W10: 23 | X10: 24
B11: 24 | C11: 25 | D11: 26 | E11: 27 | F11: 28 | G11: 29 | H11: 30 | J11: 28 | K11: 29 | L11: 30 | M11: 31 | R11: 25 | S11: 26 | T11: 27 | U11: 28 | V11: 29 | W11: 30
B13: HE | C13: 1 | D13: 1 | E13: 1 | F13: 2 | G13: 2 | H13: 1 | J13: HE | K13: 5 | L13: 5 | M13: 4 | N13: 4 | O13: 4 | P13: 3 | R13: HE | S13: 2 | T13: 2 | U13: 2 | V13: 3 | W13: 3 | X13: 3
B15: BULAN OKTOBER 2023 | J15: BULAN NOPEMBER 2023 | R15: BULAN DESEMBER 2023
B16: Minggu | C16: Senin | D16: Selasa | E16: Rabu | F16: Kamis | G16: Jum'at | H16: Sabtu | J16: Minggu | K16: Senin | L16: Selasa | M16: Rabu | N16: Kamis | O16: Jum'at | P16: Sabtu | R16: Minggu | S16: Senin | T16: Selasa | U16: Rabu | V16: Kamis | W16: Jum'at | X16: Sabtu
H17: 1 | L17: 1 | M17: 2 | N17: 3 | O17: 4 | P17: 5 | V17: 1 | W17: 2 | X17: 3
B18: 2 | C18: 3 | D18: 4 | E18: 5 | F18: 6 | G18: 7 | H18: 8 | J18: 6 | K18: 7 | L18: 8 | M18: 9 | N18: 10 | O18: 11 | P18: 12 | R18: 4 | S18: 5 | T18: 6 | U18: 7 | V18: 8 | W18: 9 | X18: 10
B19: 9 | C19: 10 | D19: 11 | E19: 12 | F19: 13 | G19: 14 | H19: 15 | J19: 13 | K19: 14 | L19: 15 | M19: 16 | N19: 17 | O19: 18 | P19: 19 | R19: 11 | S19: 12 | T19: 13 | U19: 14 | V19: 15 | W19: 16 | X19: 17
B20: 16 | C20: 17 | D20: 18 | E20: 19 | F20: 20 | G20: 21 | H20: 22 | J20: 20 | K20: 21 | L20: 22 | M20: 23 | N20: 24 | O20: 25 | P20: 26 | R20: 18 | S20: 19 | T20: 20 | U20: 21 | V20: 22 | W20: 23 | X20: 24
B21: 23 | C21: 24 | D21: 25 | E21: 26 | F21: 27 | G21: 28 | H21: 29 | J21: 27 | K21: 28 | L21: 29 | M21: 30 | R21: 25 | S21: 26 | T21: 27 | U21: 28 | V21: 29 | W21: 30 | X21: 31
B22: 30 | C22: 31
B24: HE | C24: 4 | D24: 3 | E24: 3 | F24: 3 | G24: 3 | H24: 3 | J24: HE | K24: 4 | L24: 5 | M24: 5 | N24: 4 | O24: 4 | P24: 4 | R24: HE | S24: 0 | T24: 0 | U24: 0 | V24: 1 | W24: 1 | X24: 1
B26: BULAN JANUARI 2024 | J26: BULAN PEBRUARI 2024 | R26: BULAN MARET 2024
B27: Minggu | C27: Senin | D27: Selasa | E27: Rabu | F27: Kamis | G27: Jum'at | H27: Sabtu | J27: Minggu | K27: Senin | L27: Selasa | M27: Rabu | N27: Kamis | O27: Jum'at | P27: Sabtu | R27: Minggu | S27: Senin | T27: Selasa | U27: Rabu | V27: Kamis | W27: Jum'at | X27: Sabtu
B28: 1 | C28: 2 | D28: 3 | E28: 4 | F28: 5 | G28: 6 | H28: 7 | M28: 1 | N28: 2 | O28: 3 | P28: 4 | U28: 1 | V28: 2 | W28: 3 | X28: 4
B29: 8 | C29: 9 | D29: 10 | E29: 11 | F29: 12 | G29: 13 | H29: 14 | J29: 5 | K29: 6 | L29: 7 | M29: 8 | N29: 9 | O29: 10 | P29: 11 | R29: 5 | S29: 6 | T29: 7 | U29: 8 | V29: 9 | W29: 10 | X29: 11
B30: 15 | C30: 16 | D30: 17 | E30: 18 | F30: 19 | G30: 20 | H30: 21 | J30: 12 | K30: 13 | L30: 14 | M30: 15 | N30: 16 | O30: 17 | P30: 18 | R30: 12 | S30: 13 | T30: 14 | U30: 15 | V30: 16 | W30: 17 | X30: 18
B31: 22 | C31: 23 | D31: 24 | E31: 25 | F31: 26 | G31: 27 | H31: 28 | J31: 19 | K31: 20 | L31: 21 | M31: 22 | N31: 23 | O31: 24 | P31: 25 | R31: 19 | S31: 20 | T31: 21 | U31: 22 | V31: 23 | W31: 24 | X31: 25
B32: 29 | C32: 30 | D32: 31 | J32: 26 | K32: 27 | L32: 28 | R32: 26 | S32: 27 | T32: 28 | U32: 29 | V32: 30 | W32: 31
B34: HE | C34: 3 | D34: 4 | E34: 3 | F34: 3 | G34: 3 | H34: 3 | J34: HE | K34: 3 | L34: 4 | M34: 4 | N34: 4 | O34: 3 | P34: 3 | R34: HE | S34: 2 | T34: 2 | U34: 3 | V34: 2 | W34: 2 | X34: 1
B36: BULAN APRIL 2024 | J36: BULAN MEI 2024 | R36: BULAN JUNI 2024
B37: Minggu | C37: Senin | D37: Selasa | E37: Rabu | F37: Kamis | G37: Jum'at | H37: Sabtu | J37: Minggu | K37: Senin | L37: Selasa | M37: Rabu | N37: Kamis | O37: Jum'at | P37: Sabtu | R37: Minggu | S37: Senin | T37: Selasa | U37: Rabu | V37: Kamis | W37: Jum'at | X37: Sabtu
H38: 1 | K38: 1 | L38: 2 | M38: 3 | N38: 4 | O38: 5 | P38: 6 | V38: 1 | W38: 2 | X38: 3
B39: 2 | C39: 3 | D39: 4 | E39: 5 | F39: 6 | G39: 7 | H39: 8 | J39: 7 | K39: 8 | L39: 9 | M39: 10 | N39: 11 | O39: 12 | P39: 13 | R39: 4 | S39: 5 | T39: 6 | U39: 7 | V39: 8 | W39: 9 | X39: 10
B40: 9 | C40: 10 | D40: 11 | E40: 12 | F40: 13 | G40: 14 | H40: 15 | J40: 14 | K40: 15 | L40: 16 | M40: 17 | N40: 18 | O40: 19 | P40: 20 | R40: 11 | S40: 12 | T40: 13 | U40: 14 | V40: 15 | W40: 16 | X40: 17
B41: 16 | C41: 17 | D41: 18 | E41: 19 | F41: 20 | G41: 21 | H41: 22 | J41: 21 | K41: 22 | L41: 23 | M41: 24 | N41: 25 | O41: 26 | P41: 27 | R41: 18 | S41: 19 | T41: 20 | U41: 21 | V41: 22 | W41: 23 | X41: 24
B42: 23 | C42: 24 | D42: 25 | E42: 26 | F42: 27 | G42: 28 | H42: 29 | J42: 28 | K42: 29 | L42: 30 | M42: 31 | R42: 25 | S42: 26 | T42: 27 | U42: 28 | V42: 29 | W42: 30
B43: 30
B45: HE | C45: 0 | D45: 0 | E45: 0 | F45: 0 | G45: 0 | H45: 1 | J45: HE | K45: 4 | L45: 5 | M45: 5 | N45: 3 | O45: 4 | P45: 3 | R45: HE | S45: 0 | T45: 0 | U45: 0 | V45: 0 | W45: 1 | X45: 1
N46: Banjar, 01 Juli 2022
B47: JUMLAH HARI EFEKTIF TAHUN | N47: Kepala UPTD SDN 1 Sukamukti
B48: PELAJARAN 2022-2023
...

Sheet Kalender
A1: KALENDER PENDIDIKAN
A2: UPTD SEKOLAH DASAR NEGERI 1 SUKAMUKTI
A3: TAHUN PELAJARAN 2025 - 2026
AP4: S | AQ4: S | AR4: R | AS4: K | AT4: J | AU4: S
A5: THN | B5: SMT | C5: BULAN | D5: TANGGAL | AI5: JUMLAH
D6: 1 | E6: 2 | F6: 3 | G6: 4 | H6: 5 | I6: 6 | J6: 7 | K6: 8 | L6: 9 | M6: 10 | N6: 11 | O6: 12 | P6: 13 | Q6: 14 | R6: 15 | S6: 16 | T6: 17 | U6: 18 | V6: 19 | W6: 20 | X6: 21 | Y6: 22 | Z6: 23 | AA6: 24 | AB6: 25 | AC6: 26 | AD6: 27 | AE6: 28 | AF6: 29 | AG6: 30 | AH6: 31 | AI6: HSM | AJ6: HL | AK6: IS | AL6: HE | AM6: HK
A7: 2025 | B7: GASAL | C7: JULI | D7: LS | E7: LS | F7: LS | G7: LS | H7: S/M | I7: S/M | J7: LS | K7: LS | L7: LS | M7: LS | N7: LS | O7: S/M | P7: S/M | Q7: MB | V7: S/M | W7: S/M | AC7: S/M | AD7: S/M | AI7: 8 | AJ7: 9 | AK7: 5 | AL7: 9 | AM7: =SUM(AI7:AL7) -> 31 | AP7: 2 | AQ7: 2 | AR7: 2 | AS7: 2 | AT7: 1 | AU7: 0 | AV7: =SUM(AP7:AU7) -> 9
C8: AGUSTUS | E8: S/M | F8: S/M | L8: S/M | M8: S/M | Q8: HB | S8: S/M | T8: S/M | Z8: S/M | AA8: S/M | AB8: P K | AC8: P K | AD8: P K | AE8: P K | AF8: P K | AG8: S/M | AH8: S/M | AI8: 10 | AJ8: 0 | AK8: 1 | AL8: 20 | AM8: =SUM(AI8:AL8) -> 31 | AP8: 4 | AQ8: 4 | AR8: 4 | AS8: 3 | AT8: 5 | AU8: 0 | AV8: =SUM(AP8:AU8) -> 20
C9: SEPTEMBER | H9: LN | I9: S/M | J9: S/M | O9: HB | P9: S/M | Q9: S/M | W9: S/M | X9: S/M | Y9: AN | Z9: AN | AA9: AN | AB9: AN | AD9: S/M | AE9: S/M | AI9: 8 | AJ9: 1 | AK9: 5 | AL9: 16 | AM9: =SUM(AI9:AL9) -> 30 | AP9: 3 | AQ9: 4 | AR9: 3 | AS9: 3 | AT9: 3 | AU9: 0 | AV9: =SUM(AP9:AU9) -> 16
C10: OKTOBER | G10: S/M | H10: S/M | N10: S/M | O10: S/M | U10: S/M | V10: S/M | AB10: S/M | AC10: S/M | AD10: P K | AE10: P K | AF10: P K | AG10: P K | AH10: P K | AI10: 8 | AJ10: 0 | AK10: 0 | AL10: 23 | AM10: =SUM(AI10:AL10) -> 31 | AP10: 4 | AQ10: 4 | AR10: 5 | AS10: 5 | AT10: 5 | AU10: 0 | AV10: =SUM(AP10:AU10) -> 23
C11: NOPEMBER | D11: S/M | E11: S/M | K11: S/M | L11: S/M | R11: S/M | S11: S/M | Y11: S/M | Z11: S/M | AB11: HB | AF11: S/M | AG11: S/M | AI11: 10 | AJ11: 0 | AK11: 1 | AL11: 19 | AM11: =SUM(AI11:AL11) -> 30 | AP11: 4 | AQ11: 3 | AR11: 4 | AS11: 4 | AT11: 4 | AU11: 0 | AV11: =SUM(AP11:AU11) -> 19
C12: DESEMBER | D12: P K | E12: P K | F12: P K | G12: P K | H12: P K | I12: S/M | J12: S/M | K12: SAS | L12: SAS | M12: SAS | N12: SAS | O12: SAS | P12: S/M | Q12: S/M | R12: SAS | S12: SAS | T12: SAS | U12: SAS | V12: SAS | W12: S/M | X12: S/M | Y12: PR | Z12: PR | AA12: R | AB12: LN | AC12: LN | AD12: S/M | AE12: S/M | AF12: LS | AG12: LS | AH12: LS | AI12: 8 | AJ12: 5 | AK12: 13 | AL12: 5 | AM12: =SUM(AI12:AL12) -> 31 | AP12: 1 | AQ12: 1 | AR12: 1 | AS12: 1 | AT12: 1 | AU12: 0 | AV12: =SUM(AP12:AU12) -> 5
A13: JUMLAH | AI13: =SUM(AI7:AI12) -> 52 | AJ13: =SUM(AJ7:AJ12) -> 15 | AK13: =SUM(AK7:AK12) -> 25 | AL13: =SUM(AL7:AL12) -> 92 | AM13: =SUM(AM7:AM12) -> 184 | AP13: =SUM(AP6:AP12) -> 18 | AQ13: =SUM(AQ6:AQ12) -> 18 | AR13: =SUM(AR6:AR12) -> 19 | AS13: =SUM(AS6:AS12) -> 18 | AT13: =SUM(AT6:AT12) -> 19 | AU13: =SUM(AU6:AU12) -> 0 | AV13: =SUM(AV6:AV12) -> 92
A15: THN | B15: SMT | C15: BULAN | D15: TANGGAL | AI15: JUMLAH | AP15: S | AQ15: S | AR15: R | AS15: K | AT15: J | AU15: S | AV15: JML
D16: 1 | E16: 2 | F16: 3 | G16: 4 | H16: 5 | I16: 6 | J16: 7 | K16: 8 | L16: 9 | M16: 10 | N16: 11 | O16: 12 | P16: 13 | Q16: 14 | R16: 15 | S16: 16 | T16: 17 | U16: 18 | V16: 19 | W16: 20 | X16: 21 | Y16: 22 | Z16: 23 | AA16: 24 | AB16: 25 | AC16: 26 | AD16: 27 | AE16: 28 | AF16: 29 | AG16: 30 | AH16: 31 | AI16: HM | AJ16: HL | AK16: IS | AL16: HE | AM16: HK
A17: 2026 | B17: GENAP | C17: JANUARI | D17: LN | E17: LS | F17: S/M | G17: S/M | H17: LS | I17: LS | J17: LS | K17: LS | L17: LS | M17: S/M | N17: S/M | O17: MB | S17: LN | T17: S/M | U17: S/M | V17: HB | AA17: S/M | AB17: S/M | AH17: S/M | AI17: 9 | AJ17: 8 | AK17: 2 | AL17: 12 | AM17: =SUM(AI17:AL17) -> 31 | AP17: 1 | AQ17: 3 | AR17: 3 | AS17: 3 | AT17: 2 | AU17: 0 | AV17: =SUM(AP17:AU17) -> 12
C18: FEBRUARI | D18: S/M | J18: S/M | K18: S/M | Q18: S/M | R18: S/M | T18: LN | W18: RIF | X18: S/M | Y18: S/M | Z18: RIF | AA18: P K | AB18: P K | AC18: P K | AD18: P K | AE18: S/M | AI18: 8 | AJ18: 3 | AK18: 0 | AL18: 17 | AM18: =SUM(AI18:AL18) -> 28 | AP18: 3 | AQ18: 4 | AR18: 4 | AS18: 3 | AT18: 3 | AU18: 0 | AV18: =SUM(AP18:AU18) -> 17
C19: MARET | D19: S/M | J19: S/M | K19: S/M | L19: PBP | M19: PBP | N19: PBP | O19: PBP | P19: PBP | Q19: S/M | R19: S/M | S19: RIF | T19: RIF | U19: RIF | V19: LN | W19: RIF | X19: S/M | Y19: S/M | Z19: RIF | AA19: RIF | AB19: RIF | AC19: RIF | AD19: RIF | AE19: S/M | AF19: S/M | AI19: 9 | AJ19: 10 | AK19: 5 | AL19: 7 | AM19: =SUM(AI19:AL19) -> 31 | AP19: 2 | AQ19: 2 | AR19: 1 | AS19: 1 | AT19: 1 | AU19: 0 | AV19: =SUM(AP19:AU19) -> 7
C20: APRIL | F20: LN | G20: S/M | H20: S/M | N20: S/M | O20: S/M | P20: P K | Q20: P K | R20: P K | S20: P K | T20: P K | U20: S/M | V20: S/M | W20: SAS | X20: SAS | Y20: SAS | Z20: SAS | AA20: SAS | AB20: S/M | AC20: S/M | AD20: SAS | AE20: SAS | AF20: SAS | AG20: SAS | AI20: 8 | AJ20: 1 | AK20: 0 | AL20: 21 | AM20: =SUM(AI20:AL20) -> 30 | AP20: 4 | AQ20: 4 | AR20: 4 | AS20: 5 | AT20: 4 | AU20: 0 | AV20: =SUM(AP20:AU20) -> 21
C21: MEI | D21: LN | E21: S/M | F21: S/M | L21: S/M | M21: S/M | N21: ASAJ | O21: ASAJ | P21: ASAJ | Q21: ASAJ | R21: ASAJ | S21: S/M | T21: S/M | U21: ASAJ | V21: ASAJ | W21: ASAJ | X21: ASAJ | Y21: ASAJ | Z21: S/M | AA21: S/M | AC21: LN | AD21: LN | AG21: S/M | AH21: S/M | AI21: 10 | AJ21: 3 | AK21: 5 | AL21: 13 | AM21: =SUM(AI21:AL21) -> 31 | AP21: 3 | AQ21: 2 | AR21: 2 | AS21: 3 | AT21: 3 | AU21: 0 | AV21: =SUM(AP21:AU21) -> 13
C22: JUNI | D22: LN | E22: P K | F22: P K | G22: P K | H22: P K | I22: S/M | J22: S/M | K22: SAS | L22: SAS | M22: SAS | N22: SAS | O22: SAS | P22: S/M | Q22: S/M | R22: SAS | S22: LN | T22: SAS | U22: SAS | V22: SAS | W22: S/M | X22: S/M | Y22: PR | Z22: PR | AA22: PR | AB22: PR | AC22: R | AD22: S/M | AE22: S/M | AF22: LS | AG22: LS | AI22: 8 | AJ22: 4 | AK22: 14 | AL22: 4 | AM22: =SUM(AI22:AL22) -> 30 | AP22: 0 | AQ22: 1 | AR22: 1 | AS22: 1 | AT22: 1 | AU22: 0 | AV22: =SUM(AP22:AU22) -> 4
A23: JUMLAH | AI23: =SUM(AI17:AI22) -> 52 | AJ23: =SUM(AJ17:AJ22) -> 29 | AK23: =SUM(AK17:AK22) -> 26 | AL23: =SUM(AL17:AL22) -> 74 | AM23: =SUM(AM17:AM22) -> 181
A24: JUMLAH SEMUA | AI24: =AI23+AI13 -> 104 | AJ24: =AJ23+AJ13 -> 44 | AK24: =AK23+AK13 -> 51 | AL24: =AL23+AL13 -> 166 | AM24: =AM23+AM13 -> 365 | AP24: =SUM(AP17:AP23) -> 13 | AQ24: =SUM(AQ17:AQ23) -> 16 | AR24: =SUM(AR17:AR23) -> 15 | AS24: =SUM(AS17:AS23) -> 16 | AT24: =SUM(AT17:AT23) -> 14 | AU24: =SUM(AU17:AU23) -> 0 | AV24: =SUM(AV17:AV23) -> 74
B26: KET : | AF26: Banjar, 08 Juli 2025
B27: HARI SABTU/ MINGGU | K27: S/ M | N27: SAS SMT II KHUSUS KELAS VI TERTULIS | Z27: SAS | AF27: Kepala, | AR27: =AP24+AP13 -> 31 | AS27: =AQ24+AQ13 -> 34 | AT27: =AR24+AR13 -> 34 | AU27: =AS24+AS13 -> 34 | AV27: =AT24+AT13 -> 33 | AW27: =AU24+AU13 -> 0 | AX27: =AV24+AV13 -> 166
B28: HARI PERTAMA MASUK DAN DAFTAR ULANG | K28: MB | N28: SAS SMT II KHUSUS KELAS VI PRAKTEK | Z28: SAS | AF28: UPTD SD Negeri 1 Sukamukti
B29: LIBUR NASIONAL/CUTI BERSAMA | K29: LN | N29: PESANTREN KILAT/ PENUMBUHAN BUDI PEKERTI | Z29: PBP | AX29: =AX27/6 -> 27.666667
B30: LIBUR SEKOLAH | K30: LS | N30: LIBUR AWAL RAMADHAN/ SEKITAR IDUL FITRI | Z30: RIF
B31: MPLS DAN PENDIDIKAN KEPRAMUKAAN | N31: PELAKSANAAN PEMBELAJARAN KOKURIKULER | Z31: P K
B32: MASA TRANSISI PAUD-SD KHUSUS KELAS I | N32: PEMBAGIAN RAPORT | Z32: R
B33: ASESMEN SUMATIF AHIR JENJANG TERTULIS | K33: ASAJ | N33: PENGISIAN RAPORT | Z33: PR
B34: ASESMEN SUMATIF AHIR JENJANG PRAKTEK | K34: ASAJ | N34: JUMLAH HARI MINGGU | Z34: HM
B35: PERINGATAN HARI BESAR | K35: HB | N35: JUMLAH HARI LIBUR | Z35: HL | AF35: DUDUNG, S.Pd.SD.
B36: PELAKSANAAN ASESSMEN NASIONAL | K36: AN | N36: JUMLAH HARI ISTIMEWA | Z36: IS | AF36: NIP. 19711110 199307 1 001
B37: SAS SEMESTER I/II TERTULIS | K37: SAS | N37: JUMLAH HARI EFEKTIF | Z37: HE
B38: SAS SEMESTER I/II PRAKTEK | K38: SAS | N38: JUMLAH HARI KESELURUHAN | Z38: HK

Sheet H. Efektif
B1: ANALISIS HARI BELAJAR EFEKTIF | P1: 1
B2: KALENDER PENDIDIKAN SEKOLAH DASAR
B3: =Kalender!A2 -> UPTD SEKOLAH DASAR NEGERI 1 SUKAMUKTI
B4: SEMESTER I TAHUN PELAJARAN 2025 / 2026
C6: HARI | D6: SENIN | E6: SELASA | F6: RABU | G6: KAMIS | H6: JUMAT | I6: SABTU | J6: JUMLAH | K6: KEGIATAN
B7: BULAN
B9: JULI | D9: =Kalender!AP7 -> 2 | E9: =Kalender!AQ7 -> 2 | F9: =Kalender!AR7 -> 2 | G9: =Kalender!AS7 -> 2 | H9: =Kalender!AT7 -> 1 | I9: =Kalender!AU7 -> 0 | J9: =SUM(D9:I9) -> 9 | K9: - 1 Juli s.d. 11 Juli 2025 Libur Akhir Tahun Pelajaran 2024-2025
K10: - 14 Juli 2025 Awal Masuk Sekolah/ Daftar Ulang Murid Baru
K11: - 14 Juli s.d. 18 Juli 2025 Masa Pengenalan Lingkungan Sekolah dan Pendidikan Kepramukaan Tahun 2025-2026
K12: - 21 Juli s.d. 25 Juli 2025 Masa Transisi PAUD-SD Tahun 2025 / 2026 (Khusus Kelas I)
B13: AGUSTUS | D13: =Kalender!AP8 -> 4 | E13: =Kalender!AQ8 -> 4 | F13: =Kalender!AR8 -> 4 | G13: =Kalender!AS8 -> 3 | H13: =Kalender!AT8 -> 5 | I13: =Kalender!AU8 -> 0 | J13: =SUM(D13:I15) -> 20 | K13: - 14 Agustus 2025 HUT Pramuka ke 64
K14: - 17 Agustus 2025 HUT Kemerdekaan Republik Indonesia ke 80
K15: - 25 Agustus S.D. 29 Agustus 2025 Pelaksanaan Pembelajaran Kokurikuler
B16: SEPTEMBER | D16: =Kalender!AP9 -> 3 | E16: =Kalender!AQ9 -> 4 | F16: =Kalender!AR9 -> 3 | G16: =Kalender!AS9 -> 3 | H16: =Kalender!AT9 -> 3 | I16: =Kalender!AU9 -> 0 | J16: =SUM(D16:I18) -> 16 | K16: - 05 September 2025 Libur Peringatan Maulid Nabi Muhammad SAW. 1447 H
K17: - 12 September 2025 Peringatan Maulid Nabi Muhammad SAW 1447 H di sekolah (Penumbuhan Budi Pekerti)
K18: - 22 September s.d. 25 September 2025 Perkiraan Pelaksanaan Asessmen Nasional
B19: OKTOBER | D19: =Kalender!AP10 -> 4 | E19: =Kalender!AQ10 -> 4 | F19: =Kalender!AR10 -> 5 | G19: =Kalender!AS10 -> 5 | H19: =Kalender!AT10 -> 5 | I19: =Kalender!AU10 -> 0 | J19: =SUM(D19:I20) -> 23 | K19: - 27 Oktober S.D. 31 Oktober 2025 Pelaksanaan Pembelajaran Kokurikuler
B21: NOPEMBER | D21: =Kalender!AP11 -> 4 | E21: =Kalender!AQ11 -> 3 | F21: =Kalender!AR11 -> 4 | G21: =Kalender!AS11 -> 4 | H21: =Kalender!AT11 -> 4 | I21: =Kalender!AU11 -> 0 | J21: =SUM(D21:I22) -> 19 | K21: - 25 Nopember Peringatan Hari Guru Nasional/ PGRI
B23: DESEMBER | D23: =Kalender!AP12 -> 1 | E23: =Kalender!AQ12 -> 1 | F23: =Kalender!AR12 -> 1 | G23: =Kalender!AS12 -> 1 | H23: =Kalender!AT12 -> 1 | I23: =Kalender!AU12 -> 0 | J23: =SUM(D23:I23) -> 5 | K23: - 2 Desember s.d. 5 Desember 2025 Pelaksanaan Pembelajaran Kokurikuler
K24: - 8 Desember s.d. 12 Desember 2025 Perkiraan SAS Tertulis Semester 1 Tahun Pelajaran 2025 / 2026
K25: - 15 Desember s.d. 19 Desember 2025 Perkiraan SAS Praktek Semester 1 Tahun Pelajaran 2025 / 2026
K26: - 15 Desember s.d. 23 Desember 2025 Pengolahan dan Pengisian Raport Semester 1 Tahun 2025 / 2026
K27: - 24 Desember 2025 Pembagian Raport Semester 1 Tahun Pelajaran 2025 / 2026
K28: (Titimangsa Raport Tanggal 24 Desember 2025)
K29: - 25 Desember s.d. 26 Desember 2025 Libur dan Cuti Bersama Hari Natal
K30: - 29 Desember s.d. 31 Desember 2025 Libur Akhir Semester 1 Tahun Pelajaran 2025 / 2026
B31: JUMLAH | D31: =SUM(D9:D30) -> 18 | E31: =SUM(E9:E30) -> 18 | F31: =SUM(F9:F30) -> 19 | G31: =SUM(G9:G30) -> 18 | H31: =SUM(H9:H30) -> 19 | I31: =SUM(I9:I30) -> 0 | J31: =SUM(J9:J30) -> 92
L33: Banjar, 08 Juli 2025
L34: ="Kepala "&Kalender!AF28 -> Kepala UPTD SD Negeri 1 Sukamukti
L38: =Kalender!AF35 -> DUDUNG, S.Pd.SD.
L39: =Kalender!AF36 -> NIP. 19711110 199307 1 001
B41: ANALISIS HARI BELAJAR EFEKTIF
B42: KALENDER PENDIDIKAN SEKOLAH DASAR | P42: 2
B43: =B3 -> UPTD SEKOLAH DASAR NEGERI 1 SUKAMUKTI
B44: SEMESTER II TAHUN PELAJARAN 2025 / 2026
C46: HARI | D46: SENIN | E46: SELASA | F46: RABU | G46: KAMIS | H46: JUMAT | I46: SABTU | J46: JUMLAH | K46: KEGIATAN
B47: BULAN
B49: JANUARI | D49: =Kalender!AP17 -> 1 | E49: =Kalender!AQ17 -> 3 | F49: =Kalender!AR17 -> 3 | G49: =Kalender!AS17 -> 3 | H49: =Kalender!AT17 -> 2 | I49: =Kalender!AU17 -> 0 | J49: =SUM(D49:I49) -> 12 | K49: - 1 Januari 2026 libur Tahun Baru
K50: - 2 Januari s.d. 9 Januari 2026 Libur Akhir Semester 1 Tahun Pelajaran 2025 / 2026
K51: - 12 Januari 2026 Awal masuk semester 2 Tahun Pelajaran 2025 / 2026
...

Sheet Jumlah JP
C1: JUMLAH JAM PELAJARAN
C2: KURIKULUM KTSP 2006 DAN 2013
C4: KELAS | E4: Pen. Agama | F4: PKn | G4: B. Indonesia | H4: Matematika | I4: IPA | J4: IPS | K4: SBDP | L4: PJOK | N4: B. Sunda | O4: B. Inggris | P4: PLH | Q4: JUMLAH
B7: 2013 | C7: I | E7: 4 | L7: 4 | Q7: =SUM(E7:P7) -> 8
C9: II | E9: 3 | F9: 2 | G9: 5 | H9: 5 | I9: 4 | J9: 3 | K9: 3 | L9: 4 | N9: 2 | Q9: =SUM(E9:P9) -> 31
C11: III | E11: 4 | F11: 2 | G11: 4 | H11: 5 | I11: 4 | J11: 3 | K11: 3 | L11: 4 | N11: 2 | Q11: =SUM(E11:P11) -> 31
B13: 2013 | C13: IV | E13: 4 | F13: 2 | G13: 6 | H13: 6 | I13: 4 | J13: 3 | K13: 4 | L13: 4 | N13: 2 | Q13: =SUM(E13:P13) -> 35
C15: V | E15: 4 | F15: 2 | G15: 5 | H15: 5 | I15: 4 | J15: 3 | K15: 4 | L15: 4 | N15: 2 | O15: 2 | P15: 1 | Q15: =SUM(E15:P15) -> 36
C17: VI | E17: 4 | F17: 2 | G17: 5 | H17: 5 | I17: 4 | J17: 3 | K17: 4 | L17: 4 | N17: 2 | O17: 2 | P17: 1 | Q17: =SUM(E17:P17) -> 36
C22: PEMBAGIAN JAM PELAJARAN 7 Kls
C24: WAJIB | P24: TAMBAHAN WAJIB | AC24: Jumlah Total
C25: Dudung | D25: Kartiman | E25: Juariah | F25: Nani | G25: Ati | H25: Lukman | I25: Fani | J25: Muji | K25: Angga | L25: Meli | M25: Roni | N25: Jumlah | P25: Dudung | Q25: Kartiman | R25: Juariah | S25: Nani | T25: Ati | U25: Lukman | V25: Fani | W25: Muji | X25: 0 | Y25: Meli | Z25: Roni | AA25: Jumlah
B28: Kelas I | G28: 24 | H28: 4 | K28: 4 | N28: =SUM(C28:M28) -> 32 | AA28: =SUM(P28:Z28) -> 0 | AC28: =AA28+N28 -> 32
B30: Kelas Ii | F30: 26 | H30: 4 | K30: 4 | N30: =SUM(C30:M30) -> 34 | AA30: =SUM(P30:Z30) -> 0 | AC30: =AA30+N30 -> 34
B32: Kelas III | H32: 4 | K32: 4 | L32: 28 | N32: =SUM(C32:M32) -> 36 | AA32: =SUM(P32:Z32) -> 0 | AC32: =AA32+N32 -> 36
B34: Kelas III | H34: 4 | M34: 32 | N34: =SUM(C34:M34) -> 36 | AA34: =SUM(P34:Z34) -> 0 | AC34: =AA34+N34 -> 36
B36: Kelas IV | H36: 4 | J36: 30 | K36: 4 | N36: =SUM(C36:M36) -> 38 | AA36: =SUM(P36:Z36) -> 0 | AC36: =AA36+N36+J42 -> 38
B38: Kelas V | H38: 4 | I38: 30 | K38: 4 | N38: =SUM(C38:M38) -> 38 | AA38: =SUM(P38:Z38) -> 0 | AC38: =AA38+N38 -> 38
B40: Kelas VI | E40: 30 | H40: 4 | K40: 4 | N40: =SUM(C40:M40) -> 38 | AA40: =SUM(P40:Z40) -> 0 | AC40: =AA40+N40 -> 38
N42: =SUM(C42:M42) -> 0
C45: =SUM(C27:C44) -> 0 | D45: =SUM(D27:D44) -> 0 | E45: =SUM(E27:E44) -> 30 | F45: =SUM(F27:F44) -> 26 | G45: =SUM(G27:G44) -> 24 | H45: =SUM(H27:H44) -> 28 | I45: =SUM(I27:I44) -> 30 | J45: =SUM(J27:J44) -> 30 | ... M45: =SUM(M27:M44) -> 32 | P45: =SUM(P28:P40) -> 0 | Q45: =SUM(Q28:Q40) -> 0 | R45: =SUM(R28:R40) -> 0 | S45: =SUM(S28:S40) -> 0 | T45: =SUM(T28:T40) -> 0 | U45: =SUM(U28:U40) -> 0 | V45: =SUM(V28:V40) -> 0 | W45: =SUM(W28:W40) -> 0 | ... Z45: =SUM(Z28:Z40) -> 0
D46: Guru Kelaas | E46: Guru Kelaas | F46: Guru Kelaas | G46: Guru Kelaas & B. Sunda | H46: Guru PJOK | I46: Guru Kelaas & B. Sunda | J46: Guru Kelaas & B. Sunda | K46: Guru PAI/ PABD | L46: Guru Kelaas | M46: Guru PAI , Mate | Q46: B. Sunda | X46: Guru PAI/ PABD | Y46: b. Sunda | Z46: Guru PAI, Mulok B. Sunda dan B. Inggris
AC47: =SUM(AC28:AC40) -> 252
B49: Jumlah Total Guru | C49: =C45+P45 -> 0 | D49: =D45+Q45 -> 0 | E49: =E45+R45 -> 30 | F49: =F45+S45 -> 26 | G49: =G45+T45 -> 24 | H49: =H45+U45 -> 28 | I49: =I45+V45 -> 30 | J49: =J45+W45 -> 30 | ... M49: =M45+Z45 -> 32 | AC49: =SUM(C49:M49) -> 252
C54: PEMBAGIAN JAM PELAJARAN 6 Kls
C56: WAJIB | P56: TAMBAHAN WAJIB | AC56: Jumlah Total
C57: Dudung | D57: Kartiman | E57: Juariah | F57: Nani | G57: Ati | H57: Lukman | I57: Inglan | J57: Muji | K57: Roni | L57: Rinda | N57: Jumlah | P57: Dudung | Q57: Kartiman | R57: Juariah | S57: Nani | T57: Ati | U57: Lukman | V57: Inglan | W57: Muji | X57: Roni | Y57: Rinda | AA57: Jumlah
B60: Kelas I | G60: 24 | H60: 4 | K60: 4 | N60: =SUM(C60:L60) -> 32 | AA60: =SUM(P60:Y60) -> 0 | AC60: =AA60+N60 -> 32
B62: Kelas I
B64: Kelas II | F64: 24 | H64: 2 | K64: 2 | N64: =SUM(C64:L64) -> 28 | U64: 2 | X64: 1 | AA64: =SUM(P64:Y64) -> 3 | AC64: =AA64+N64 -> 31
B66: Kelas III | H66: 2 | K66: 2 | L66: 24 | N66: =SUM(C66:L66) -> 28 | U66: 2 | X66: 2 | AA66: =SUM(P66:Y66) -> 4 | AC66: =AA66+N66 -> 32
B68: Kelas IV | H68: 4 | J68: 28 | K68: 4 | N68: =SUM(C68:L68) -> 36 | V68: 2 | AA68: =SUM(P68:Y68) -> 2 | AC68: =AA68+N68 -> 38
B70: Kelas V | D70: 25 | H70: 4 | K70: 3 | N70: =SUM(C70:L70) -> 32 | Q70: 1 | V70: 2 | X70: 1 | AA70: =SUM(P70:Y70) -> 4 | AC70: =AA70+N70 -> 36
B72: Kelas VI | E72: 25 | H72: 4 | K72: 3 | N72: =SUM(C72:L72) -> 32 | V72: 2 | X72: 2 | AA72: =SUM(P72:Y72) -> 4 | AC72: =AA72+N72 -> 36
C73: =SUM(C60:C72) -> 0 | D73: =SUM(D60:D72) -> 25 | E73: =SUM(E60:E72) -> 25 | F73: =SUM(F60:F72) -> 24 | G73: =SUM(G60:G72) -> 24 | H73: =SUM(H60:H72) -> 20 | I73: =SUM(I60:I72) -> 0 | J73: =SUM(J60:J72) -> 28 | ... L73: =SUM(L60:L72) -> 24 | P73: =SUM(P60:P72) -> 0 | Q73: =SUM(Q60:Q72) -> 1 | R73: =SUM(R60:R72) -> 0 | S73: =SUM(S60:S72) -> 0 | T73: =SUM(T60:T72) -> 0 | U73: =SUM(U60:U72) -> 4 | V73: =SUM(V60:V72) -> 6 | W73: =SUM(W60:W72) -> 0 | ... Y73: =SUM(Y60:Y72) -> 0
D74: Guru Kelaas(24)+ B. Sunda (2) | E74: Guru Kelaas(24)+ B. Sunda (1) | F74: Guru Kelaas(22)+ B. Sunda (2) | G74: Guru Kelaas(22)+ B. Sunda (2) | H74: Guru PJOK | I74: Guru Kelaas | J74: Guru Kelaas | K74: Guru PAI/ PABD | L74: Guru Kelaas(22)+ B. Sunda (2) | Q74: B. Sunda | U74: Guru PJOK | V74: B. Sunda + B. Inggris | W74: B. Sunda | X74: PAI
B77: Jumlah Total Guru | C77: =C73+P73 -> 0 | D77: =D73+Q73 -> 26 | E77: =E73+R73 -> 25 | F77: =F73+S73 -> 24 | G77: =G73+T73 -> 24 | H77: =H73+U73 -> 24 | I77: =I73+V73 -> 6 | J77: =J73+W73 -> 28 | ... L77: =L73+Y73 -> 24

Sheet Jadwal Kokuli Blok
B1: JADWAL PELAJARAN DENGAN P5 BLOK DAN KURANGI 2 JP ( KELAS 3,4,5,6)
B3: JADWAL PELAJARAN
B4: TAHUN PELAJARAN 2025-2026
B5: KELAS I A
C6: B. Sunda
B7: JAM KE | C7: WAKTU | D7: SENIN | E7: SELASA | F7: RABU | G7: KAMIS | H7: JUM'AT
B9: 1 | C9: 06.31-07.05 | D9: UPACARA | E9: PEMBIASAAN | F9: PEMBIASAAN | G9: PEMBIASAAN | H9: PEMBIASAAN
B10: 2 | C10: 07.06-07.40 | D10: B. Indonesia | E10: Pendidikan Pancasila | F10: P J O K | G10: PAdBP | H10: B. Indonesia
B11: 3 | C11: 07.41-08.15 | D11: B. Indonesia | E11: Pendidikan Pancasila | F11: P J O K | G11: PAdBP | H11: B. Indonesia
B12: 4 | C12: 08.16-08.50 | D12: B. Indonesia | E12: Seni dan Budaya | F12: P J O K | G12: PAdBP | H12: Matematika
B13: 5 | C13: 08.51-09.25 | D13: Seni dan Budaya | E13: Seni dan Budaya | F13: P J O K | G13: PAdBP | H13: Matematika
B14: 6 | C14: 09.26-09.55 | D14: ISTIRAHAT | E14: ISTIRAHAT | F14: ISTIRAHAT | G14: ISTIRAHAT | H14: ISTIRAHAT
B15: 7 | C15: 09.56-10.30 | D15: Seni dan Budaya | E15: Matematika | F15: B. Indonesia | G15: Pendidikan Pancasila
B16: 8 | C16: 10.31-11.05 | D16: B. Sunda | E16: Matematika | F16: B. Indonesia | G16: Pendidikan Pancasila
B17: 9 | C17: 11.06-11.40 | D17: B. Sunda | E17: Matematika | F17: B. Indonesia | G17: Pendidikan Pancasila
B20: JADWAL PELAJARAN
B21: TAHUN PELAJARAN 2025-2026
B22: KELAS I B
B24: JAM KE | C24: WAKTU | D24: SENIN | E24: SELASA | F24: RABU | G24: KAMIS | H24: JUM'AT
B26: 1 | C26: 06.31-07.05 | D26: UPACARA | E26: PEMBIASAAN | F26: PEMBIASAAN | G26: PEMBIASAAN | H26: PEMBIASAAN
B27: 2 | C27: 07.06-07.40 | D27: B. Indonesia | E27: Pendidikan Pancasila | F27: PAdBP | G27: P J O K | H27: B. Indonesia
B28: 3 | C28: 07.41-08.15 | D28: B. Indonesia | E28: Pendidikan Pancasila | F28: PAdBP | G28: P J O K | H28: B. Indonesia
B29: 4 | C29: 08.16-08.50 | D29: B. Indonesia | E29: Seni dan Budaya | F29: PAdBP | G29: P J O K | H29: Matematika
B30: 5 | C30: 08.51-09.25 | D30: Seni dan Budaya | E30: Seni dan Budaya | F30: PAdBP | G30: P J O K | H30: Matematika
B31: 6 | C31: 09.26-09.55 | D31: ISTIRAHAT | E31: ISTIRAHAT | F31: ISTIRAHAT | G31: ISTIRAHAT | H31: ISTIRAHAT
B32: 7 | C32: 09.56-10.30 | D32: Seni dan Budaya | E32: Matematika | F32: B. Indonesia | G32: Pendidikan Pancasila
B33: 8 | C33: 10.31-11.05 | D33: B. Sunda | E33: Matematika | F33: B. Indonesia | G33: Pendidikan Pancasila
B34: 9 | C34: 11.06-11.40 | D34: B. Sunda | E34: Matematika | F34: B. Indonesia | G34: Pendidikan Pancasila
B38: JADWAL PELAJARAN
B39: TAHUN PELAJARAN 2025-2026
B40: KELAS II
B42: JAM KE | C42: WAKTU | D42: SENIN | E42: SELASA | F42: RABU | G42: KAMIS | H42: JUM'AT
B44: 1 | C44: 06.31-07.05 | D44: UPACARA | E44: PEMBIASAAN | F44: PEMBIASAAN | G44: PEMBIASAAN | H44: PEMBIASAAN
B45: 2 | C45: 07.06-07.40 | D45: B. Indonesia | E45: PAdBP | F45: B. Sunda | G45: Pendidikan Pancasila | H45: P J O K
B46: 3 | C46: 07.41-08.15 | D46: B. Indonesia | E46: PAdBP | F46: B. Sunda | G46: Pendidikan Pancasila | H46: P J O K
B47: 4 | C47: 08.16-08.50 | D47: B. Indonesia | E47: PAdBP | F47: B. Indonesia | G47: Matematika | H47: P J O K
B48: 5 | C48: 08.51-09.25 | D48: Pendidikan Pancasila | E48: PAdBP | F48: B. Indonesia | G48: Matematika | H48: P J O K
B49: 6 | C49: 09.26-09.55 | D49: ISTIRAHAT | E49: ISTIRAHAT | F49: ISTIRAHAT | G49: ISTIRAHAT | H49: ISTIRAHAT
B50: 7 | C50: 09.56-10.30 | D50: Pendidikan Pancasila | E50: Pendidikan Pancasila | F50: B. Indonesia | G50: B. Indonesia | H50: Seni dan Budaya
B51: 8 | C51: 10.31-11.05 | D51: Matematika | E51: Pendidikan Pancasila | F51: Seni dan Budaya | G51: B. Indonesia | H51: Seni dan Budaya
...

Sheet Hitung JP Kelas
B1: ANALISIS JUMLAH JAM PELAJARAN EPEKTIF
B2: TAHUN PELAJARAN 2025-2026 SEMESTER 1
B3: KELAS . . . .
B5: NO | C5: MATA PELEJARAN | D5: SENIN | F5: SELASA | H5: RABU | J5: KAMIS | L5: JUM'AT | N5: SABTU | P5: JUMLAH JP EPEKTIF
D6: ='H. Efektif'!D31-3 -> 15 | F6: ='H. Efektif'!E31-3 -> 15 | H6: ='H. Efektif'!F31-3 -> 16 | J6: ='H. Efektif'!G31-3 -> 15 | L6: ='H. Efektif'!H31-3 -> 16 | N6: ='H. Efektif'!I31 -> 0
B8: 1 | C8: PAIdBP/ PAdBP | E8: =D8*D6 -> 0 | G8: =F8*F6 -> 0 | I8: =H8*H6 -> 0 | K8: =J8*J6 -> 0 | M8: =L8*L6 -> 0 | O8: =N8*N6 -> 0 | P8: =E8+G8+I8+K8+M8+O8 -> 0 | T8: 1 | U8: 14
B9: 2 | C9: Pendidikan Pancasila | E9: =D9*D6 -> 0 | G9: =F9*F6 -> 0 | I9: =H9*H6 -> 0 | K9: =J9*J6 -> 0 | M9: =L9*L6 -> 0 | O9: =N9*N6 -> 0 | P9: =E9+G9+I9+K9+M9+O9 -> 0 | R9: =P9-12 -> -12 | T9: 2 | U9: 14
B10: 3 | C10: Bahasa Indonesia | E10: =D10*D6 -> 0 | G10: =F10*F6 -> 0 | I10: =H10*H6 -> 0 | K10: =J10*J6 -> 0 | M10: =L10*L6 -> 0 | O10: =N10*N6 -> 0 | P10: =E10+G10+I10+K10+M10+O10 -> 0 | T10: 3 | U10: 14
B11: 4 | C11: Matematika | E11: =D11*D6 -> 0 | G11: =F11*F6 -> 0 | I11: =H11*H6 -> 0 | K11: =J11*J6 -> 0 | M11: =L11*L6 -> 0 | O11: =N11*N6 -> 0 | P11: =E11+G11+I11+K11+M11+O11 -> 0 | T11: 4 | U11: 12
B12: 5 | C12: IPAS | E12: =D12*D6 -> 0 | G12: =F12*F6 -> 0 | I12: =H12*H6 -> 0 | K12: =J12*J6 -> 0 | M12: =L12*L6 -> 0 | O12: =N12*N6 -> 0 | P12: =E12+G12+I12+K12+M12+O12 -> 0
B13: 6 | C13: Seni dan Budaya/ SBDP | E13: =D13*D6 -> 0 | G13: =F13*F6 -> 0 | I13: =H13*H6 -> 0 | K13: =J13*J6 -> 0 | M13: =L13*L6 -> 0 | O13: =N13*N6 -> 0 | P13: =E13+G13+I13+K13+M13+O13 -> 0 | U13: =SUM(U8:U12) -> 54
B14: 7 | C14: PJOK | E14: =D14*D6 -> 0 | G14: =F14*F6 -> 0 | I14: =H14*H6 -> 0 | K14: =J14*J6 -> 0 | M14: =L14*L6 -> 0 | O14: =N14*N6 -> 0 | P14: =E14+G14+I14+K14+M14+O14 -> 0
B15: 8 | C15: Bahasa dan Sastra Sunda | E15: =D15*D6 -> 0 | G15: =F15*F6 -> 0 | I15: =H15*H6 -> 0 | K15: =J15*J6 -> 0 | M15: =L15*L6 -> 0 | O15: =N15*N6 -> 0 | P15: =E15+G15+I15+K15+M15+O15 -> 0
B16: 9 | E16: =D16*D6 -> 0 | G16: =F16*F6 -> 0 | I16: =H16*H6 -> 0 | K16: =J16*J6 -> 0 | M16: =L16*L6 -> 0 | O16: =N16*N6 -> 0 | P16: =E16+G16+I16+K16+M16+O16 -> 0
B17: 10 | E17: =D17*D6 -> 0 | G17: =F17*F6 -> 0 | I17: =H17*H6 -> 0 | K17: =J17*J6 -> 0 | M17: =L17*L6 -> 0 | O17: =N17*N6 -> 0 | P17: =E17+G17+I17+K17+M17+O17 -> 0
B23: ANALISIS JUMLAH JAM PELAJARAN EPEKTIF
B24: TAHUN PELAJARAN 2025-2026 SEMESTER 2
B25: KELAS . . . . .
B27: NO | C27: MATA PELEJARAN | D27: SENIN | F27: SELASA | H27: RABU | J27: KAMIS | L27: JUM'AT | N27: SABTU | P27: JUMLAH JP EPEKTIF
D28: ='H. Efektif'!D77-1 -> 12 | F28: ='H. Efektif'!E77-3 -> 13 | H28: ='H. Efektif'!F77-3 -> 12 | J28: ='H. Efektif'!G77-3 -> 13 | L28: ='H. Efektif'!H77-3 -> 11 | N28: ='H. Efektif'!I77 -> 0
B30: 1 | C30: PAIdBP/ PAdBP | E30: =D30*D28 -> 0 | G30: =F30*F28 -> 0 | I30: =H30*H28 -> 0 | K30: =J30*J28 -> 0 | M30: =L30*L28 -> 0 | O30: =N30*N28 -> 0 | P30: =E30+G30+I30+K30+M30+O30 -> 0
B31: 2 | C31: Pendidikan Pancasila | E31: =D31*D28 -> 0 | G31: =F31*F28 -> 0 | I31: =H31*H28 -> 0 | K31: =J31*J28 -> 0 | M31: =L31*L28 -> 0 | O31: =N31*N28 -> 0 | P31: =E31+G31+I31+K31+M31+O31 -> 0
B32: 3 | C32: Bahasa Indonesia | E32: =D32*D28 -> 0 | G32: =F32*F28 -> 0 | I32: =H32*H28 -> 0 | K32: =J32*J28 -> 0 | M32: =L32*L28 -> 0 | O32: =N32*N28 -> 0 | P32: =E32+G32+I32+K32+M32+O32 -> 0
B33: 4 | C33: Matematika | E33: =D33*D28 -> 0 | G33: =F33*F28 -> 0 | I33: =H33*H28 -> 0 | K33: =J33*J28 -> 0 | M33: =L33*L28 -> 0 | O33: =N33*N28 -> 0 | P33: =E33+G33+I33+K33+M33+O33 -> 0
B34: 5 | C34: IPAS | E34: =D34*D28 -> 0 | G34: =F34*F28 -> 0 | I34: =H34*H28 -> 0 | K34: =J34*J28 -> 0 | M34: =L34*L28 -> 0 | O34: =N34*N28 -> 0 | P34: =E34+G34+I34+K34+M34+O34 -> 0
B35: 6 | C35: Seni dan Budaya/ SBDP | E35: =D35*D28 -> 0 | G35: =F35*F28 -> 0 | I35: =H35*H28 -> 0 | K35: =J35*J28 -> 0 | M35: =L35*L28 -> 0 | O35: =N35*N28 -> 0 | P35: =E35+G35+I35+K35+M35+O35 -> 0
B36: 7 | C36: PJOK | E36: =D36*D28 -> 0 | G36: =F36*F28 -> 0 | I36: =H36*H28 -> 0 | K36: =J36*J28 -> 0 | M36: =L36*L28 -> 0 | O36: =N36*N28 -> 0 | P36: =E36+G36+I36+K36+M36+O36 -> 0
B37: 8 | C37: Bahasa dan Sastra Sunda | E37: =D37*D28 -> 0 | G37: =F37*F28 -> 0 | I37: =H37*H28 -> 0 | K37: =J37*J28 -> 0 | M37: =L37*L28 -> 0 | O37: =N37*N28 -> 0 | P37: =E37+G37+I37+K37+M37+O37 -> 0
B38: 9 | E38: =D38*D28 -> 0 | G38: =F38*F28 -> 0 | I38: =H38*H28 -> 0 | K38: =J38*J28 -> 0 | M38: =L38*L28 -> 0 | O38: =N38*N28 -> 0 | P38: =E38+G38+I38+K38+M38+O38 -> 0
B39: 10 | E39: =D39*D28 -> 0 | G39: =F39*F28 -> 0 | I39: =H39*H28 -> 0 | K39: =J39*J28 -> 0 | M39: =L39*L28 -> 0 | O39: =N39*N28 -> 0 | P39: =E39+G39+I39+K39+M39+O39 -> 0

Sheet Hitung JP Mapel
B1: ANALISIS JUMLAH JAM PELAJARAN EPEKTIF
B2: TAHUN PELAJARAN 2025-2026 SEMESTER 1
B3: MATA PELAJARAN …...................................
B5: NO | C5: KELAS | D5: SENIN | F5: SELASA | H5: RABU | J5: KAMIS | L5: JUM'AT | N5: SABTU | P5: JUMLAH JP EPEKTIF
D6: ='Hitung JP Kelas'!D6 -> 15 | F6: ='Hitung JP Kelas'!F6 -> 15 | H6: ='Hitung JP Kelas'!H6 -> 16 | J6: ='Hitung JP Kelas'!J6 -> 15 | L6: ='Hitung JP Kelas'!L6 -> 16 | N6: ='H. Efektif'!I31 -> 0
B8: 1 | C8: KELAS I | E8: =D8*D6 -> 0 | G8: =F8*F6 -> 0 | I8: =H8*H6 -> 0 | K8: =J8*J6 -> 0 | M8: =L8*L6 -> 0 | O8: =N8*N6 -> 0 | P8: =E8+G8+I8+K8+M8+O8 -> 0
B9: 2 | C9: KELAS II A | E9: =D9*D6 -> 0 | G9: =F9*F6 -> 0 | I9: =H9*H6 -> 0 | K9: =J9*J6 -> 0 | M9: =L9*L6 -> 0 | O9: =N9*N6 -> 0 | P9: =E9+G9+I9+K9+M9+O9 -> 0
B10: 3 | C10: KELAS II B | E10: =D10*D6 -> 0 | G10: =F10*F6 -> 0 | I10: =H10*H6 -> 0 | K10: =J10*J6 -> 0 | M10: =L10*L6 -> 0 | O10: =N10*N6 -> 0 | P10: =E10+G10+I10+K10+M10+O10 -> 0
B11: 4 | C11: KELAS III | E11: =D11*D6 -> 0 | G11: =F11*F6 -> 0 | I11: =H11*H6 -> 0 | K11: =J11*J6 -> 0 | M11: =L11*L6 -> 0 | O11: =N11*N6 -> 0 | P11: =E11+G11+I11+K11+M11+O11 -> 0
B12: 5 | C12: KELAS IV | E12: =D12*D6 -> 0 | G12: =F12*F6 -> 0 | I12: =H12*H6 -> 0 | K12: =J12*J6 -> 0 | M12: =L12*L6 -> 0 | O12: =N12*N6 -> 0 | P12: =E12+G12+I12+K12+M12+O12 -> 0
B13: 6 | C13: KELAS V | E13: =D13*D6 -> 0 | G13: =F13*F6 -> 0 | I13: =H13*H6 -> 0 | K13: =J13*J6 -> 0 | M13: =L13*L6 -> 0 | O13: =N13*N6 -> 0 | P13: =E13+G13+I13+K13+M13+O13 -> 0
B14: 7 | C14: KELAS VI | E14: =D14*D6 -> 0 | G14: =F14*F6 -> 0 | I14: =H14*H6 -> 0 | K14: =J14*J6 -> 0 | M14: =L14*L6 -> 0 | O14: =N14*N6 -> 0 | P14: =E14+G14+I14+K14+M14+O14 -> 0
B15: 8 | E15: =D15*D6 -> 0 | G15: =F15*F6 -> 0 | I15: =H15*H6 -> 0 | K15: =J15*J6 -> 0 | M15: =L15*L6 -> 0 | O15: =N15*N6 -> 0 | P15: =E15+G15+I15+K15+M15+O15 -> 0
B16: 9 | E16: =D16*D6 -> 0 | G16: =F16*F6 -> 0 | I16: =H16*H6 -> 0 | K16: =J16*J6 -> 0 | M16: =L16*L6 -> 0 | O16: =N16*N6 -> 0 | P16: =E16+G16+I16+K16+M16+O16 -> 0
B17: 10 | E17: =D17*D6 -> 0 | G17: =F17*F6 -> 0 | I17: =H17*H6 -> 0 | K17: =J17*J6 -> 0 | M17: =L17*L6 -> 0 | O17: =N17*N6 -> 0 | P17: =E17+G17+I17+K17+M17+O17 -> 0
B22: ANALISIS JUMLAH JAM PELAJARAN EPEKTIF
B23: TAHUN PELAJARAN 2025-2026 SEMESTER 2
B24: MATA PELAJARAN …...................................
B26: NO | C26: KELAS | D26: SENIN | F26: SELASA | H26: RABU | J26: KAMIS | L26: JUM'AT | N26: SABTU | P26: JUMLAH JP EPEKTIF
D27: ='Hitung JP Kelas'!D28 -> 12 | F27: ='Hitung JP Kelas'!F28 -> 13 | H27: ='Hitung JP Kelas'!H28 -> 12 | J27: ='Hitung JP Kelas'!J28 -> 13 | L27: ='Hitung JP Kelas'!L28 -> 11 | N27: ='H. Efektif'!I77 -> 0
B29: 1 | C29: KELAS I | E29: =D29*D27 -> 0 | G29: =F29*F27 -> 0 | H29: 4 | I29: =H29*H27 -> 48 | K29: =J29*J27 -> 0 | M29: =L29*L27 -> 0 | O29: =N29*N27 -> 0 | P29: =E29+G29+I29+K29+M29+O29 -> 48
B30: 2 | C30: KELAS II A | E30: =D30*D27 -> 0 | G30: =F30*F27 -> 0 | I30: =H30*H27 -> 0 | K30: =J30*J27 -> 0 | M30: =L30*L27 -> 0 | N30: 2 | O30: =N30*N27 -> 0 | P30: =E30+G30+I30+K30+M30+O30 -> 0
B31: 3 | C31: KELAS II B | E31: =D31*D27 -> 0 | G31: =F31*F27 -> 0 | I31: =H31*H27 -> 0 | K31: =J31*J27 -> 0 | M31: =L31*L27 -> 0 | O31: =N31*N27 -> 0 | P31: =E31+G31+I31+K31+M31+O31 -> 0
B32: 4 | C32: KELAS III | E32: =D32*D27 -> 0 | G32: =F32*F27 -> 0 | I32: =H32*H27 -> 0 | K32: =J32*J27 -> 0 | M32: =L32*L27 -> 0 | O32: =N32*N27 -> 0 | P32: =E32+G32+I32+K32+M32+O32 -> 0
B33: 5 | C33: KELAS IV | E33: =D33*D27 -> 0 | G33: =F33*F27 -> 0 | I33: =H33*H27 -> 0 | K33: =J33*J27 -> 0 | M33: =L33*L27 -> 0 | O33: =N33*N27 -> 0 | P33: =E33+G33+I33+K33+M33+O33 -> 0
B34: 6 | C34: KELAS V | E34: =D34*D27 -> 0 | G34: =F34*F27 -> 0 | I34: =H34*H27 -> 0 | K34: =J34*J27 -> 0 | M34: =L34*L27 -> 0 | O34: =N34*N27 -> 0 | P34: =E34+G34+I34+K34+M34+O34 -> 0
B35: 7 | C35: KELAS VI | E35: =D35*D27 -> 0 | G35: =F35*F27 -> 0 | I35: =H35*H27 -> 0 | K35: =J35*J27 -> 0 | M35: =L35*L27 -> 0 | O35: =N35*N27 -> 0 | P35: =E35+G35+I35+K35+M35+O35 -> 0
B36: 8 | E36: =D36*D27 -> 0 | G36: =F36*F27 -> 0 | I36: =H36*H27 -> 0 | K36: =J36*J27 -> 0 | M36: =L36*L27 -> 0 | O36: =N36*N27 -> 0 | P36: =E36+G36+I36+K36+M36+O36 -> 0
B37: 9 | E37: =D37*D27 -> 0 | G37: =F37*F27 -> 0 | I37: =H37*H27 -> 0 | K37: =J37*J27 -> 0 | M37: =L37*L27 -> 0 | O37: =N37*N27 -> 0 | P37: =E37+G37+I37+K37+M37+O37 -> 0
B38: 10 | E38: =D38*D27 -> 0 | G38: =F38*F27 -> 0 | I38: =H38*H27 -> 0 | K38: =J38*J27 -> 0 | M38: =L38*L27 -> 0 | O38: =N38*N27 -> 0 | P38: =E38+G38+I38+K38+M38+O38 -> 0

Sheet lmpiran KTSP 
B3: LAMPIRAN 3
A4: KALENDER PENDIDIKAN
A5: UPTD SEKOLAH DASAR NEGERI 1 SUKAMUKTI
A6: TAHUN PELAJARAN 2025 - 2026
A8: THN | B8: SMT | C8: BULAN | D8: TANGGAL | AI8: JUMLAH
D9: 1 | E9: 2 | F9: 3 | G9: 4 | H9: 5 | I9: 6 | J9: 7 | K9: 8 | L9: 9 | M9: 10 | N9: 11 | O9: 12 | P9: 13 | Q9: 14 | R9: 15 | S9: 16 | T9: 17 | U9: 18 | V9: 19 | W9: 20 | X9: 21 | Y9: 22 | Z9: 23 | AA9: 24 | AB9: 25 | AC9: 26 | AD9: 27 | AE9: 28 | AF9: 29 | AG9: 30 | AH9: 31 | AI9: HSM | AJ9: HL | AK9: IS | AL9: HE | AM9: HK
A10: 2025 | B10: GASAL | C10: JULI | D10: LS | E10: LS | F10: LS | G10: LS | H10: S/M | I10: S/M | J10: LS | K10: LS | L10: LS | M10: LS | N10: LS | O10: S/M | P10: S/M | Q10: MB | V10: S/M | W10: S/M | AC10: S/M | AD10: S/M | AI10: 8 | AJ10: 9 | AK10: 5 | AL10: 9 | AM10: =SUM(AI10:AL10) -> 31
C11: AGUSTUS | E11: S/M | F11: S/M | L11: S/M | M11: S/M | Q11: HB | S11: S/M | T11: S/M | Z11: S/M | AA11: S/M | AB11: P 5 | AC11: P 5 | AD11: P 5 | AE11: P 5 | AF11: P 5 | AG11: S/M | AH11: S/M | AI11: 10 | AJ11: 0 | AK11: 1 | AL11: 20 | AM11: =SUM(AI11:AL11) -> 31
C12: SEPTEMBER | H12: LN | I12: S/M | J12: S/M | O12: HB | P12: S/M | Q12: S/M | W12: S/M | X12: S/M | Y12: AN | Z12: AN | AA12: AN | AB12: AN | AD12: S/M | AE12: S/M | AI12: 8 | AJ12: 1 | AK12: 5 | AL12: 16 | AM12: =SUM(AI12:AL12) -> 30
C13: OKTOBER | G13: S/M | H13: S/M | N13: S/M | O13: S/M | U13: S/M | V13: S/M | AB13: S/M | AC13: S/M | AD13: P 5 | AE13: P 5 | AF13: P 5 | AG13: P 5 | AH13: P 5 | AI13: 8 | AJ13: 0 | AK13: 0 | AL13: 23 | AM13: =SUM(AI13:AL13) -> 31
C14: NOPEMBER | D14: S/M | E14: S/M | K14: S/M | L14: S/M | R14: S/M | S14: S/M | Y14: S/M | Z14: S/M | AB14: HB | AF14: S/M | AG14: S/M | AI14: 10 | AJ14: 0 | AK14: 1 | AL14: 19 | AM14: =SUM(AI14:AL14) -> 30
C15: DESEMBER | D15: P 5 | E15: P 5 | F15: P 5 | G15: P 5 | H15: P 5 | I15: S/M | J15: S/M | K15: SAS | L15: SAS | M15: SAS | N15: SAS | O15: SAS | P15: S/M | Q15: S/M | R15: SAS | S15: SAS | T15: SAS | U15: SAS | V15: SAS | W15: S/M | X15: S/M | Y15: PR | Z15: PR | AA15: R | AB15: LN | AC15: LN | AD15: S/M | AE15: S/M | AF15: LS | AG15: LS | AH15: LS | AI15: 8 | AJ15: 5 | AK15: 13 | AL15: 5 | AM15: =SUM(AI15:AL15) -> 31
A16: JUMLAH | AI16: =SUM(AI10:AI15) -> 52 | AJ16: =SUM(AJ10:AJ15) -> 15 | AK16: =SUM(AK10:AK15) -> 25 | AL16: =SUM(AL10:AL15) -> 92 | AM16: =SUM(AM10:AM15) -> 184
A18: THN | B18: SMT | C18: BULAN | D18: TANGGAL | AI18: JUMLAH
D19: 1 | E19: 2 | F19: 3 | G19: 4 | H19: 5 | I19: 6 | J19: 7 | K19: 8 | L19: 9 | M19: 10 | N19: 11 | O19: 12 | P19: 13 | Q19: 14 | R19: 15 | S19: 16 | T19: 17 | U19: 18 | V19: 19 | W19: 20 | X19: 21 | Y19: 22 | Z19: 23 | AA19: 24 | AB19: 25 | AC19: 26 | AD19: 27 | AE19: 28 | AF19: 29 | AG19: 30 | AH19: 31 | AI19: HM | AJ19: HL | AK19: IS | AL19: HE | AM19: HK
A20: 2026 | B20: GENAP | C20: JANUARI | D20: LN | E20: LS | F20: S/M | G20: S/M | H20: LS | I20: LS | J20: LS | K20: LS | L20: LS | M20: S/M | N20: S/M | S20: LN | T20: S/M | U20: S/M | V20: HB | AA20: S/M | AB20: S/M | AH20: S/M | AI20: 9 | AJ20: 8 | AK20: 2 | AL20: 12 | AM20: =SUM(AI20:AL20) -> 31
C21: FEBRUARI | D21: S/M | J21: S/M | K21: S/M | Q21: S/M | R21: S/M | T21: LN | W21: RIF | X21: S/M | Y21: S/M | Z21: RIF | AA21: P 5 | AB21: P 5 | AC21: P 5 | AD21: P 5 | AE21: S/M | AI21: 8 | AJ21: 3 | AK21: 0 | AL21: 17 | AM21: =SUM(AI21:AL21) -> 28
C22: MARET | D22: S/M | J22: S/M | K22: S/M | L22: PBP | M22: PBP | N22: PBP | O22: PBP | P22: PBP | Q22: S/M | R22: S/M | S22: RIF | T22: RIF | U22: RIF | V22: LN | W22: RIF | X22: S/M | Y22: S/M | Z22: RIF | AA22: RIF | AB22: RIF | AC22: RIF | AD22: RIF | AE22: S/M | AF22: S/M | AI22: 9 | AJ22: 10 | AK22: 5 | AL22: 7 | AM22: =SUM(AI22:AL22) -> 31
C23: APRIL | F23: LN | G23: S/M | H23: S/M | N23: S/M | O23: S/M | P23: P 5 | Q23: P 5 | R23: P 5 | S23: P 5 | T23: P 5 | U23: S/M | V23: S/M | W23: SAS | X23: SAS | Y23: SAS | Z23: SAS | AA23: SAS | AB23: S/M | AC23: S/M | AD23: SAS | AE23: SAS | AF23: SAS | AG23: SAS | AI23: 8 | AJ23: 1 | AK23: 0 | AL23: 21 | AM23: =SUM(AI23:AL23) -> 30
C24: MEI | D24: LN | E24: S/M | F24: S/M | L24: S/M | M24: S/M | N24: ASAJ | O24: ASAJ | P24: ASAJ | Q24: ASAJ | R24: ASAJ | S24: S/M | T24: S/M | U24: ASAJ | V24: ASAJ | W24: ASAJ | X24: ASAJ | Y24: ASAJ | Z24: S/M | AA24: S/M | AC24: LN | AD24: LN | AG24: S/M | AH24: S/M | AI24: 10 | AJ24: 3 | AK24: 5 | AL24: 13 | AM24: =SUM(AI24:AL24) -> 31
C25: JUNI | D25: LN | E25: P 5 | F25: P 5 | G25: P 5 | H25: P 5 | I25: S/M | J25: S/M | K25: SAS | L25: SAS | M25: SAS | N25: SAS | O25: SAS | P25: S/M | Q25: S/M | R25: SAS | S25: LN | T25: SAS | U25: SAS | V25: SAS | W25: S/M | X25: S/M | Y25: PR | Z25: PR | AA25: PR | AB25: PR | AC25: R | AD25: S/M | AE25: S/M | AF25: LS | AG25: LS | AI25: 8 | AJ25: 4 | AK25: 14 | AL25: 4 | AM25: =SUM(AI25:AL25) -> 30
A26: JUMLAH | AI26: =SUM(AI20:AI25) -> 52 | AJ26: =SUM(AJ20:AJ25) -> 29 | AK26: =SUM(AK20:AK25) -> 26 | AL26: =SUM(AL20:AL25) -> 74 | AM26: =SUM(AM20:AM25) -> 181
A27: JUMLAH SEMUA | AI27: =AI26+AI16 -> 104 | AJ27: =AJ26+AJ16 -> 44 | AK27: =AK26+AK16 -> 51 | AL27: =AL26+AL16 -> 166 | AM27: =AM26+AM16 -> 365
B29: KET : | AD29: Banjar, 08 Juli 2025
B30: HARI SABTU/ MINGGU | K30: S/ M | N30: SAS SMT II KHUSUS KELAS VI TERTULIS | X30: SAS | AD30: Kepala,
B31: KEGIATAN PPDB DAN DAFTAR ULANG | K31: MB | N31: SAS SMT II KHUSUS KELAS VI PRAKTEK | X31: SAS | AD31: UPTD SD Negeri 1 Sukamukti
B32: LIBUR NASIONAL/CUTI BERSAMA | K32: LN | N32: PESANTREN KILAT/ PENUMBUHAN BUDI PEKERTI | X32: PBP
B33: LIBUR SEKOLAH | K33: LS | N33: LIBUR AWAL RAMADHAN/ SEKITAR IDUL FITRI | X33: RIF
B34: MPLS DAN PENDIDIKAN KEPRAMUKAAN | N34: PELAKSANAAN P 5 | X34: P 5
B35: MASA TRANSISI PAUD-SD KHUSUS KELAS I | N35: PEMBAGIAN RAPORT | X35: R
B36: ASESMEN SUMATIF AHIR JENJANG TERTULIS | K36: ASAJ | N36: PENGISIAN RAPORT | X36: PR
B37: ASESMEN SUMATIF AHIR JENJANG PRAKTEK | K37: ASAJ | N37: JUMLAH HARI MINGGU | X37: HM
B38: PERINGATAN HARI BESAR | K38: HB | N38: JUMLAH HARI LIBUR | X38: HL | AD38: DUDUNG, S.Pd.SD.
B39: PELAKSANAAN ASESSMEN NASIONAL | K39: AN | N39: JUMLAH HARI ISTIMEWA | X39: IS | AD39: NIP. 19711110 199307 1 001
B40: SAS SEMESTER I/II TERTULIS | K40: SAS | N40: JUMLAH HARI EFEKTIF | X40: HE
B41: SAS SEMESTER I/II PRAKTEK | K41: SAS | N41: JUMLAH HARI KESELURUHAN | X41: HK

Sheet Jadwal Pelajaran 6
B1: JADWAL PELAJARAN
B2: TAHUN PELAJARAN 2018-2019
B3: KELAS I
B5: JAM KE | C5: WAKTU | D5: SENIN | E5: SELASA | F5: RABU | G5: KAMIS | H5: JUM'AT | I5: SABTU
C6: 07.00-07.10 | D6: PEMBIASAAN | E6: PEMBIASAAN | F6: PEMBIASAAN | G6: PEMBIASAAN | H6: PEMBIASAAN | I6: PEMBIASAAN
B7: 1 | C7: 07.11-07.45 | D7: UPACARA | E7: GURU KELAS | F7: GURU KELAS | G7: PJOK | H7: JUM'AT SEHAT | I7: GURU KELAS
B8: 2 | C8: 07.46-08.20 | D8: PJOK | E8: GURU KELAS | F8: GURU KELAS | G8: PJOK | H8: GURU KELAS | I8: GURU KELAS
B9: 3 | C9: 08.21-08.55 | D9: PJOK | E9: PAI | F9: GURU KELAS | G9: GURU KELAS | H9: GURU KELAS | I9: PAI
B10: 4 | C10: 08.56-09.330 | D10: GURU KELAS | E10: PAI | F10: GURU KELAS | G10: GURU KELAS | H10: GURU KELAS | I10: PAI
C11: 09.31-09.50 | D11: ISTIRAHAT | E11: ISTIRAHAT | F11: ISTIRAHAT | G11: ISTIRAHAT | H11: ISTIRAHAT | I11: ISTIRAHAT
B12: 5 | C12: 09.51-10.25 | D12: GURU KELAS | E12: GURU KELAS | F12: GURU KELAS | G12: GURU KELAS | H12: GURU KELAS | I12: GURU KELAS
B13: 6 | C13: 10.26-11.00 | D13: GURU KELAS | E13: GURU KELAS | F13: GURU KELAS | G13: GURU KELAS
B14: 7 | C14: 11.01-11.35
B18: JADWAL PELAJARAN
B19: TAHUN PELAJARAN 2018-2019
B20: KELAS II
B22: JAM KE | C22: WAKTU | D22: SENIN | E22: SELASA | F22: RABU | G22: KAMIS | H22: JUM'AT | I22: SABTU
C23: 07.00-07.10 | D23: PEMBIASAAN | E23: PEMBIASAAN | F23: PEMBIASAAN | G23: PEMBIASAAN | H23: PEMBIASAAN | I23: PEMBIASAAN
B24: 1 | C24: 07.11-07.45 | D24: UPACARA | E24: PAI | F24: GURU KELAS | G24: GURU KELAS | H24: JUM'AT SEHAT | I24: PJOK
B25: 2 | C25: 07.46-08.20 | D25: GURU KELAS | E25: PAI | F25: GURU KELAS | G25: GURU KELAS | H25: GURU KELAS | I25: PJOK
B26: 3 | C26: 08.21-08.55 | D26: GURU KELAS | E26: GURU KELAS | F26: GURU KELAS | G26: PAI | H26: GURU KELAS | I26: GURU KELAS
B27: 4 | C27: 08.56-09.330 | D27: GURU KELAS | E27: GURU KELAS | F27: PJOK | G27: PAI | H27: GURU KELAS | I27: GURU KELAS
C28: 09.31-09.50 | D28: ISTIRAHAT | E28: ISTIRAHAT | F28: ISTIRAHAT | G28: ISTIRAHAT | H28: ISTIRAHAT | I28: ISTIRAHAT
B29: 5 | C29: 09.51-10.25 | D29: GURU KELAS | E29: GURU KELAS | F29: PJOK | G29: GURU KELAS | H29: GURU KELAS | I29: GURU KELAS
B30: 6 | C30: 10.26-11.00 | D30: GURU KELAS | E30: GURU KELAS | F30: GURU KELAS | G30: GURU KELAS | H30: GURU KELAS | I30: GURU KELAS
B31: 7 | C31: 11.01-11.35
B39: JADWAL PELAJARAN
B40: TAHUN PELAJARAN 2018-2019
B41: KELAS III
B43: JAM KE | C43: WAKTU | D43: SENIN | E43: SELASA | F43: RABU | G43: KAMIS | H43: JUM'AT | I43: SABTU
C44: 07.00-07.10 | D44: PEMBIASAAN | E44: PEMBIASAAN | F44: PEMBIASAAN | G44: PEMBIASAAN | H44: PEMBIASAAN | I44: PEMBIASAAN
B45: 1 | C45: 07.11-07.45 | D45: UPACARA | E45: GURU KELAS | F45: GURU KELAS | G45: GURU KELAS | H45: JUM'AT SEHAT | I45: GURU KELAS
B46: 2 | C46: 07.46-08.20 | D46: PAI | E46: GURU KELAS | F46: GURU KELAS | G46: GURU KELAS | H46: GURU KELAS | I46: GURU KELAS
B47: 3 | C47: 08.21-08.55 | D47: PAI | E47: GURU KELAS | F47: PAI | G47: GURU KELAS | H47: GURU KELAS | I47: PJOK
B48: 4 | C48: 08.56-09.330 | D48: GURU KELAS | E48: GURU KELAS | F48: PAI | G48: GURU KELAS | H48: GURU KELAS | I48: PJOK
C49: 09.31-09.50 | D49: ISTIRAHAT | E49: ISTIRAHAT | F49: ISTIRAHAT | G49: ISTIRAHAT | H49: ISTIRAHAT | I49: ISTIRAHAT
B50: 5 | C50: 09.51-10.25 | D50: GURU KELAS | E50: PJOK | F50: GURU KELAS | G50: GURU KELAS | H50: GURU KELAS | I50: GURU KELAS
B51: 6 | C51: 10.26-11.00 | D51: GURU KELAS | E51: PJOK | F51: GURU KELAS | G51: GURU KELAS
B52: 7 | C52: 11.01-11.35
B55: JADWAL PELAJARAN
...
